Workbook
Name TRANSMUTATION_TABLE: 'DO NOT DELETE'!$G$2:$J$42

Sheet INPUT DATA
A1: Input Data Sheet for E-Class Record
C4: REGION | G4: III | L4: DIVISION | O4: CITY OF SAN FDO. | T4: DISTRICT | X4: NORTH
B5: SCHOOL NAME | G5: TELABASTAGAN INTEGRATED SCHOOL | T5: SCHOOL ID | X5: 500144 | AD5: SCHOOL YEAR | AG5: 2024-2025
F7: GRADE & SECTION: | K7: VI-Venus | Q7: TEACHER: | S7: ADELIA M. MANARANG | AC7: SUBJECT: | AG7: EDUKASYON SA PAGPAPAKATAO
B8: LEARNERS' NAMES
B11: MALE
A12: 1 | B12: ='[1]INPUT DATA'!B12 -> 1. ARCEO, MARCUS ANDREW B.
A13: 2 | B13: ='[1]INPUT DATA'!B13 -> 2. CARIŇO, TOEBY YHAEL ANGELES
A14: 3 | B14: ='[1]INPUT DATA'!B14 -> 3. DE GUZMAN , YUAN KYLER D.
A15: 4 | B15: ='[1]INPUT DATA'!B15 -> 4. DE LEON ERVIC MARQUITO
A16: 5 | B16: ='[1]INPUT DATA'!B16 -> 5. DELA CRUZ, GIANVER JEAN DOMINGGO
A17: 6 | B17: ='[1]INPUT DATA'!B17 -> 6. LOMANGGYA, JON DAVID P.
A18: 7 | B18: ='[1]INPUT DATA'!B18 -> 7. LULU , RHENZ RUZZEL G.
A19: 8 | B19: ='[1]INPUT DATA'!B19 -> 8. MACAPAGAL, LACSON JR. P. | D19: 0
A20: 9 | B20: ='[1]INPUT DATA'!B20 -> 9. ORLAIN, TERENCE JERIEL D.
A21: 10 | B21: ='[1]INPUT DATA'!B21 -> 10. QUIAMBAO, JOHN LOR DELA FUENTE
A22: 11 | B22: ='[1]INPUT DATA'!B22 -> 11. RASCO, SEAN ROWEL TAMAYO | D22: 0
A23: 12 | B23: ='[1]INPUT DATA'!B23 -> 12. RELABO , PRINCE RUTHZNEIL SHELLORD C.
A24: 13 | B24: ='[1]INPUT DATA'!B24 -> 13. SABONDO, KEYLETTE - TRANS IN
A25: 14 | B25: ='[1]INPUT DATA'!B25 -> 14. SAN JUAN, THOMAS GREGORY GONZALES
A26: 15 | B26: ='[1]INPUT DATA'!B26 -> 15. TAYAG , DENVER KIEL D.
A27: 16 | B27: ='[1]INPUT DATA'!B27 -> 16. TUNGOL JOHANNES LISCOG
A28: 17 | B28: ='[1]INPUT DATA'!B28 -> 17. TUNGOL, DANIEL MADDAWIN
A29: 18 | B29: ='[1]INPUT DATA'!B29 -> 18. YUTUC , MARC ANDREI A.
A30: 19 | B30: BALUYUT, JOHN ALBERT
A31: 20 | B31: CALBARRIO, PRINCE LIAM
A32: 21
A33: 22
A34: 23
A35: 24
A36: 25 | D36: 0 | E36: 0
A37: 26 | D37: 0 | E37: 0
A38: 27 | D38: 0 | E38: 0
D39: 0 | E39: 0
A40: 29 | C40: 0 | D40: 0 | E40: 0
A41: 30 | C41: 0 | D41: 0 | E41: 0
A42: 31 | C42: 0 | D42: 0 | E42: 0
A43: 32 | C43: 0 | D43: 0 | E43: 0
A44: 33 | C44: 0 | D44: 0 | E44: 0
A45: 34 | C45: 0 | D45: 0 | E45: 0
...

Sheet EsP_Q1
A1: Official E-Class Record in K to 12 Curriculum
C4: REGION | G4: ='INPUT DATA'!G4 -> III | L4: DIVISION | O4: ='INPUT DATA'!O4 -> CITY OF SAN FDO. | T4: DISTRICT | X4: ='INPUT DATA'!X4 -> NORTH
B5: SCHOOL NAME | G5: ='INPUT DATA'!G5 -> TELABASTAGAN INTEGRATED SCHOOL | T5: SCHOOL ID | X5: ='INPUT DATA'!X5 -> 500144 | AD5: SCHOOL YEAR | AG5: ='INPUT DATA'!AG5 -> 2024-2025
A7: FIRST QUARTER | F7: GRADE & SECTION: | K7: ='INPUT DATA'!K7 -> VI-Venus | Q7: TEACHER: | S7: ='INPUT DATA'!S7 -> ADELIA M. MANARANG | AC7: SUBJECT: | AG7: ='INPUT DATA'!AG7 -> EDUKASYON SA PAGPAPAKATAO
B8: LEARNERS' NAMES | F8: WRITTEN WORKS (30%) | S8: PERFORMANCE TASKS (50%) | AF8: QUARTERLY ASSESSMENT (20%) | AI8: Initial | AJ8: Quarterly
F9: 1 | G9: 2 | H9: 3 | I9: 4 | J9: 5 | K9: 6 | L9: 7 | M9: 8 | N9: 9 | O9: 10 | P9: Total | Q9: PS | R9: WS | S9: 1 | T9: 2 | U9: 3 | V9: 4 | W9: 5 | X9: 6 | Y9: 7 | Z9: 8 | AA9: 9 | AB9: 10 | AC9: Total | AD9: PS | AE9: WS | AF9: 1 | AG9: PS | AH9: WS | AI9: 5 | AJ9: Grade
B10: HIGHEST POSSIBLE SCORE | F10: 10 | G10: 15 | H10: 10 | I10: 10 | J10: 10 | K10: 15 | L10: 10 | P10: =IF(COUNT($F10:$O10)=0,"",SUM($F10:$O10)) -> 80 | Q10: 100 | R10: 0.3 | S10: 10 | T10: 15 | U10: 15 | V10: 10 | W10: 20 | X10: 10 | Y10: 20 | AC10: =IF(COUNT($S10:$AB10)=0,"",SUM($S10:$AB10)) -> 100 | AD10: 100 | AE10: 0.5 | AF10: 50 | AG10: 100 | AH10: 0.2
B11: MALE
A12: 1 | B12: ='INPUT DATA'!B12 -> 1. ARCEO, MARCUS ANDREW B. | F12: 8 | G12: 15 | H12: 5 | I12: 7 | J12: 5 | K12: 12 | L12: 9 | P12: =IF(COUNT($F12:$O12)=0,"",SUM($F12:$O12)) -> 61 | Q12: =IF(ISERROR(IF($P12="","",ROUND(($P12/$P$10)*$Q$10,2))),"",IF($P12="","",ROUND(($P12/$P$10)*$Q$10,2))) -> 76.25 | R12: =IF($Q12="","",ROUND($Q12*$R$10,2)) -> 22.88 | S12: 8 | T12: 10 | U12: 14 | V12: 6 | W12: 15 | X12: 7 | Y12: 15 | AC12: =IF(COUNT($S12:$AB12)=0,"",SUM($S12:$AB12)) -> 75 | AD12: =IF(ISERROR(IF($AC12="","",ROUND(($AC12/$AC$10)*$AD$10,2))),"",IF($AC12="","",ROUND(($AC12/$AC$10)*$AD$10,2))) -> 75 | AE12: =IF($AD12="","",ROUND($AD12*$AE$10,2)) -> 37.5 | AF12: 38 | AG12: =IF(ISERROR(IF($AF12="","",ROUND(($AF12/$AF$10)*$AG$10,2))),"",IF($AF12="","",ROUND(($AF12/$AF$10)*$AG$10,2))) -> 76 | AH12: =IF($AG12="","",ROUND($AG12*$AH$10,2)) -> 15.2 | AI12: =IF(ISERROR(IF($AF12="","",ROUND(SUM($R12,$AE12,$AH12),2))),"",IF($AF12="","",ROUND(SUM($R12,$AE12,$AH12),2))) -> 75.58 | AJ12: =IF(ISERROR(IF($AF12="","",VLOOKUP(AI12,TRANSMUTATION_TABLE,4,TRUE))),"",IF($AF12="","",VLOOKUP(AI12,TRANSMUTATION_TABLE,4,TRUE))) -> 84
A13: 2 | B13: ='INPUT DATA'!B13 -> 2. CARIŇO, TOEBY YHAEL ANGELES | F13: 9 | G13: 13 | H13: 7 | I13: 8 | J13: 9 | K13: 10 | L13: 9 | P13: =IF(COUNT($F13:$O13)=0,"",SUM($F13:$O13)) -> 65 | Q13: =IF(ISERROR(IF($P13="","",ROUND(($P13/$P$10)*$Q$10,2))),"",IF($P13="","",ROUND(($P13/$P$10)*$Q$10,2))) -> 81.25 | R13: =IF($Q13="","",ROUND($Q13*$R$10,2)) -> 24.38 | S13: 9 | T13: 14 | U13: 14 | V13: 9 | W13: 18 | X13: 10 | Y13: 17 | AC13: =IF(COUNT($S13:$AB13)=0,"",SUM($S13:$AB13)) -> 91 | AD13: =IF(ISERROR(IF($AC13="","",ROUND(($AC13/$AC$10)*$AD$10,2))),"",IF($AC13="","",ROUND(($AC13/$AC$10)*$AD$10,2))) -> 91 | AE13: =IF($AD13="","",ROUND($AD13*$AE$10,2)) -> 45.5 | AF13: 42 | AG13: =IF(ISERROR(IF($AF13="","",ROUND(($AF13/$AF$10)*$AG$10,2))),"",IF($AF13="","",ROUND(($AF13/$AF$10)*$AG$10,2))) -> 84 | AH13: =IF($AG13="","",ROUND($AG13*$AH$10,2)) -> 16.8 | AI13: =IF(ISERROR(IF($AF13="","",ROUND(SUM($R13,$AE13,$AH13),2))),"",IF($AF13="","",ROUND(SUM($R13,$AE13,$AH13),2))) -> 86.68 | AJ13: =IF(ISERROR(IF($AF13="","",VLOOKUP(AI13,TRANSMUTATION_TABLE,4,TRUE))),"",IF($AF13="","",VLOOKUP(AI13,TRANSMUTATION_TABLE,4,TRUE))) -> 91
A14: 3 | B14: ='INPUT DATA'!B14 -> 3. DE GUZMAN , YUAN KYLER D. | F14: 9 | G14: 11 | H14: 10 | I14: 9 | J14: 6 | K14: 10 | L14: 9 | P14: =IF(COUNT($F14:$O14)=0,"",SUM($F14:$O14)) -> 64 | Q14: =IF(ISERROR(IF($P14="","",ROUND(($P14/$P$10)*$Q$10,2))),"",IF($P14="","",ROUND(($P14/$P$10)*$Q$10,2))) -> 80 | R14: =IF($Q14="","",ROUND($Q14*$R$10,2)) -> 24 | S14: 9 | T14: 14 | U14: 15 | V14: 9 | W14: 20 | X14: 10 | Y14: 20 | AC14: =IF(COUNT($S14:$AB14)=0,"",SUM($S14:$AB14)) -> 97 | AD14: =IF(ISERROR(IF($AC14="","",ROUND(($AC14/$AC$10)*$AD$10,2))),"",IF($AC14="","",ROUND(($AC14/$AC$10)*$AD$10,2))) -> 97 | AE14: =IF($AD14="","",ROUND($AD14*$AE$10,2)) -> 48.5 | AF14: 34 | AG14: =IF(ISERROR(IF($AF14="","",ROUND(($AF14/$AF$10)*$AG$10,2))),"",IF($AF14="","",ROUND(($AF14/$AF$10)*$AG$10,2))) -> 68 | AH14: =IF($AG14="","",ROUND($AG14*$AH$10,2)) -> 13.6 | AI14: =IF(ISERROR(IF($AF14="","",ROUND(SUM($R14,$AE14,$AH14),2))),"",IF($AF14="","",ROUND(SUM($R14,$AE14,$AH14),2))) -> 86.1 | AJ14: =IF(ISERROR(IF($AF14="","",VLOOKUP(AI14,TRANSMUTATION_TABLE,4,TRUE))),"",IF($AF14="","",VLOOKUP(AI14,TRANSMUTATION_TABLE,4,TRUE))) -> 91
A15: 4 | B15: ='INPUT DATA'!B15 -> 4. DE LEON ERVIC MARQUITO | F15: 8 | G15: 13 | H15: 5 | I15: 8 | J15: 5 | K15: 12 | L15: 10 | P15: =IF(COUNT($F15:$O15)=0,"",SUM($F15:$O15)) -> 61 | Q15: =IF(ISERROR(IF($P15="","",ROUND(($P15/$P$10)*$Q$10,2))),"",IF($P15="","",ROUND(($P15/$P$10)*$Q$10,2))) -> 76.25 | R15: =IF($Q15="","",ROUND($Q15*$R$10,2)) -> 22.88 | S15: 8 | T15: 12 | U15: 14 | V15: 8 | W15: 17 | X15: 10 | Y15: 15 | AC15: =IF(COUNT($S15:$AB15)=0,"",SUM($S15:$AB15)) -> 84 | AD15: =IF(ISERROR(IF($AC15="","",ROUND(($AC15/$AC$10)*$AD$10,2))),"",IF($AC15="","",ROUND(($AC15/$AC$10)*$AD$10,2))) -> 84 | AE15: =IF($AD15="","",ROUND($AD15*$AE$10,2)) -> 42 | AF15: 38 | AG15: =IF(ISERROR(IF($AF15="","",ROUND(($AF15/$AF$10)*$AG$10,2))),"",IF($AF15="","",ROUND(($AF15/$AF$10)*$AG$10,2))) -> 76 | AH15: =IF($AG15="","",ROUND($AG15*$AH$10,2)) -> 15.2 | AI15: =IF(ISERROR(IF($AF15="","",ROUND(SUM($R15,$AE15,$AH15),2))),"",IF($AF15="","",ROUND(SUM($R15,$AE15,$AH15),2))) -> 80.08 | AJ15: =IF(ISERROR(IF($AF15="","",VLOOKUP(AI15,TRANSMUTATION_TABLE,4,TRUE))),"",IF($AF15="","",VLOOKUP(AI15,TRANSMUTATION_TABLE,4,TRUE))) -> 87
A16: 5 | B16: ='INPUT DATA'!B16 -> 5. DELA CRUZ, GIANVER JEAN DOMINGGO | F16: 7 | G16: 11 | H16: 5 | I16: 7 | J16: 5 | K16: 5 | L16: 10 | P16: =IF(COUNT($F16:$O16)=0,"",SUM($F16:$O16)) -> 50 | Q16: =IF(ISERROR(IF($P16="","",ROUND(($P16/$P$10)*$Q$10,2))),"",IF($P16="","",ROUND(($P16/$P$10)*$Q$10,2))) -> 62.5 | R16: =IF($Q16="","",ROUND($Q16*$R$10,2)) -> 18.75 | S16: 7 | T16: 12 | U16: 11 | V16: 8 | W16: 10 | X16: 2 | Y16: 20 | AC16: =IF(COUNT($S16:$AB16)=0,"",SUM($S16:$AB16)) -> 70 | AD16: =IF(ISERROR(IF($AC16="","",ROUND(($AC16/$AC$10)*$AD$10,2))),"",IF($AC16="","",ROUND(($AC16/$AC$10)*$AD$10,2))) -> 70 | AE16: =IF($AD16="","",ROUND($AD16*$AE$10,2)) -> 35 | AF16: 26 | AG16: =IF(ISERROR(IF($AF16="","",ROUND(($AF16/$AF$10)*$AG$10,2))),"",IF($AF16="","",ROUND(($AF16/$AF$10)*$AG$10,2))) -> 52 | AH16: =IF($AG16="","",ROUND($AG16*$AH$10,2)) -> 10.4 | AI16: =IF(ISERROR(IF($AF16="","",ROUND(SUM($R16,$AE16,$AH16),2))),"",IF($AF16="","",ROUND(SUM($R16,$AE16,$AH16),2))) -> 64.15 | AJ16: =IF(ISERROR(IF($AF16="","",VLOOKUP(AI16,TRANSMUTATION_TABLE,4,TRUE))),"",IF($AF16="","",VLOOKUP(AI16,TRANSMUTATION_TABLE,4,TRUE))) -> 77
A17: 6 | B17: ='INPUT DATA'!B17 -> 6. LOMANGGYA, JON DAVID P. | F17: 10 | G17: 13 | H17: 10 | I17: 10 | J17: 9 | K17: 15 | L17: 5 | P17: =IF(COUNT($F17:$O17)=0,"",SUM($F17:$O17)) -> 72 | Q17: =IF(ISERROR(IF($P17="","",ROUND(($P17/$P$10)*$Q$10,2))),"",IF($P17="","",ROUND(($P17/$P$10)*$Q$10,2))) -> 90 | R17: =IF($Q17="","",ROUND($Q17*$R$10,2)) -> 27 | S17: 7 | T17: 15 | U17: 13 | V17: 7 | W17: 20 | X17: 10 | Y17: 18 | AC17: =IF(COUNT($S17:$AB17)=0,"",SUM($S17:$AB17)) -> 90 | AD17: =IF(ISERROR(IF($AC17="","",ROUND(($AC17/$AC$10)*$AD$10,2))),"",IF($AC17="","",ROUND(($AC17/$AC$10)*$AD$10,2))) -> 90 | AE17: =IF($AD17="","",ROUND($AD17*$AE$10,2)) -> 45 | AF17: 44 | AG17: =IF(ISERROR(IF($AF17="","",ROUND(($AF17/$AF$10)*$AG$10,2))),"",IF($AF17="","",ROUND(($AF17/$AF$10)*$AG$10,2))) -> 88 | AH17: =IF($AG17="","",ROUND($AG17*$AH$10,2)) -> 17.6 | AI17: =IF(ISERROR(IF($AF17="","",ROUND(SUM($R17,$AE17,$AH17),2))),"",IF($AF17="","",ROUND(SUM($R17,$AE17,$AH17),2))) -> 89.6 | AJ17: =IF(ISERROR(IF($AF17="","",VLOOKUP(AI17,TRANSMUTATION_TABLE,4,TRUE))),"",IF($AF17="","",VLOOKUP(AI17,TRANSMUTATION_TABLE,4,TRUE))) -> 93
A18: 7 | B18: ='INPUT DATA'!B18 -> 7. LULU , RHENZ RUZZEL G. | F18: 10 | G18: 13 | H18: 10 | I18: 9 | J18: 9 | K18: 15 | L18: 8 | P18: =IF(COUNT($F18:$O18)=0,"",SUM($F18:$O18)) -> 74 | Q18: =IF(ISERROR(IF($P18="","",ROUND(($P18/$P$10)*$Q$10,2))),"",IF($P18="","",ROUND(($P18/$P$10)*$Q$10,2))) -> 92.5 | R18: =IF($Q18="","",ROUND($Q18*$R$10,2)) -> 27.75 | S18: 9 | T18: 13 | U18: 13 | V18: 8 | W18: 19 | X18: 9 | Y18: 17 | AC18: =IF(COUNT($S18:$AB18)=0,"",SUM($S18:$AB18)) -> 88 | AD18: =IF(ISERROR(IF($AC18="","",ROUND(($AC18/$AC$10)*$AD$10,2))),"",IF($AC18="","",ROUND(($AC18/$AC$10)*$AD$10,2))) -> 88 | AE18: =IF($AD18="","",ROUND($AD18*$AE$10,2)) -> 44 | AF18: 30 | AG18: =IF(ISERROR(IF($AF18="","",ROUND(($AF18/$AF$10)*$AG$10,2))),"",IF($AF18="","",ROUND(($AF18/$AF$10)*$AG$10,2))) -> 60 | AH18: =IF($AG18="","",ROUND($AG18*$AH$10,2)) -> 12 | AI18: =IF(ISERROR(IF($AF18="","",ROUND(SUM($R18,$AE18,$AH18),2))),"",IF($AF18="","",ROUND(SUM($R18,$AE18,$AH18),2))) -> 83.75 | AJ18: =IF(ISERROR(IF($AF18="","",VLOOKUP(AI18,TRANSMUTATION_TABLE,4,TRUE))),"",IF($AF18="","",VLOOKUP(AI18,TRANSMUTATION_TABLE,4,TRUE))) -> 89
A19: 8 | B19: ='INPUT DATA'!B19 -> 8. MACAPAGAL, LACSON JR. P. | D19: 0 | F19: 8 | G19: 5 | H19: 5 | I19: 8 | J19: 5 | K19: 11 | L19: 5 | P19: =IF(COUNT($F19:$O19)=0,"",SUM($F19:$O19)) -> 47 | Q19: =IF(ISERROR(IF($P19="","",ROUND(($P19/$P$10)*$Q$10,2))),"",IF($P19="","",ROUND(($P19/$P$10)*$Q$10,2))) -> 58.75 | R19: =IF($Q19="","",ROUND($Q19*$R$10,2)) -> 17.63 | S19: 8 | T19: 12 | U19: 12 | V19: 9 | W19: 15 | X19: 10 | Y19: 15 | AC19: =IF(COUNT($S19:$AB19)=0,"",SUM($S19:$AB19)) -> 81 | AD19: =IF(ISERROR(IF($AC19="","",ROUND(($AC19/$AC$10)*$AD$10,2))),"",IF($AC19="","",ROUND(($AC19/$AC$10)*$AD$10,2))) -> 81 | AE19: =IF($AD19="","",ROUND($AD19*$AE$10,2)) -> 40.5 | AF19: 6 | AG19: =IF(ISERROR(IF($AF19="","",ROUND(($AF19/$AF$10)*$AG$10,2))),"",IF($AF19="","",ROUND(($AF19/$AF$10)*$AG$10,2))) -> 12 | AH19: =IF($AG19="","",ROUND($AG19*$AH$10,2)) -> 2.4 | AI19: =IF(ISERROR(IF($AF19="","",ROUND(SUM($R19,$AE19,$AH19),2))),"",IF($AF19="","",ROUND(SUM($R19,$AE19,$AH19),2))) -> 60.53 | AJ19: =IF(ISERROR(IF($AF19="","",VLOOKUP(AI19,TRANSMUTATION_TABLE,4,TRUE))),"",IF($AF19="","",VLOOKUP(AI19,TRANSMUTATION_TABLE,4,TRUE))) -> 75
A20: 9 | B20: ='INPUT DATA'!B20 -> 9. ORLAIN, TERENCE JERIEL D. | F20: 7 | G20: 6 | H20: 2 | I20: 8 | J20: 7 | K20: 11 | L20: 7 | P20: =IF(COUNT($F20:$O20)=0,"",SUM($F20:$O20)) -> 48 | Q20: =IF(ISERROR(IF($P20="","",ROUND(($P20/$P$10)*$Q$10,2))),"",IF($P20="","",ROUND(($P20/$P$10)*$Q$10,2))) -> 60 | R20: =IF($Q20="","",ROUND($Q20*$R$10,2)) -> 18 | S20: 9 | T20: 12 | U20: 14 | V20: 8 | W20: 12 | X20: 10 | Y20: 15 | AC20: =IF(COUNT($S20:$AB20)=0,"",SUM($S20:$AB20)) -> 80 | AD20: =IF(ISERROR(IF($AC20="","",ROUND(($AC20/$AC$10)*$AD$10,2))),"",IF($AC20="","",ROUND(($AC20/$AC$10)*$AD$10,2))) -> 80 | AE20: =IF($AD20="","",ROUND($AD20*$AE$10,2)) -> 40 | AF20: 36 | AG20: =IF(ISERROR(IF($AF20="","",ROUND(($AF20/$AF$10)*$AG$10,2))),"",IF($AF20="","",ROUND(($AF20/$AF$10)*$AG$10,2))) -> 72 | AH20: =IF($AG20="","",ROUND($AG20*$AH$10,2)) -> 14.4 | AI20: =IF(ISERROR(IF($AF20="","",ROUND(SUM($R20,$AE20,$AH20),2))),"",IF($AF20="","",ROUND(SUM($R20,$AE20,$AH20),2))) -> 72.4 | AJ20: =IF(ISERROR(IF($AF20="","",VLOOKUP(AI20,TRANSMUTATION_TABLE,4,TRUE))),"",IF($AF20="","",VLOOKUP(AI20,TRANSMUTATION_TABLE,4,TRUE))) -> 82
A21: 10 | B21: ='INPUT DATA'!B21 -> 10. QUIAMBAO, JOHN LOR DELA FUENTE | F21: 9 | G21: 14 | H21: 5 | I21: 9 | J21: 10 | K21: 5 | L21: 10 | P21: =IF(COUNT($F21:$O21)=0,"",SUM($F21:$O21)) -> 62 | Q21: =IF(ISERROR(IF($P21="","",ROUND(($P21/$P$10)*$Q$10,2))),"",IF($P21="","",ROUND(($P21/$P$10)*$Q$10,2))) -> 77.5 | R21: =IF($Q21="","",ROUND($Q21*$R$10,2)) -> 23.25 | S21: 6 | T21: 11 | U21: 14 | V21: 8 | W21: 15 | X21: 7 | Y21: 15 | AC21: =IF(COUNT($S21:$AB21)=0,"",SUM($S21:$AB21)) -> 76 | AD21: =IF(ISERROR(IF($AC21="","",ROUND(($AC21/$AC$10)*$AD$10,2))),"",IF($AC21="","",ROUND(($AC21/$AC$10)*$AD$10,2))) -> 76 | AE21: =IF($AD21="","",ROUND($AD21*$AE$10,2)) -> 38 | AF21: 42 | AG21: =IF(ISERROR(IF($AF21="","",ROUND(($AF21/$AF$10)*$AG$10,2))),"",IF($AF21="","",ROUND(($AF21/$AF$10)*$AG$10,2))) -> 84 | AH21: =IF($AG21="","",ROUND($AG21*$AH$10,2)) -> 16.8 | AI21: =IF(ISERROR(IF($AF21="","",ROUND(SUM($R21,$AE21,$AH21),2))),"",IF($AF21="","",ROUND(SUM($R21,$AE21,$AH21),2))) -> 78.05 | AJ21: =IF(ISERROR(IF($AF21="","",VLOOKUP(AI21,TRANSMUTATION_TABLE,4,TRUE))),"",IF($AF21="","",VLOOKUP(AI21,TRANSMUTATION_TABLE,4,TRUE))) -> 86
A22: 11 | B22: ='INPUT DATA'!B22 -> 11. RASCO, SEAN ROWEL TAMAYO | D22: 0 | F22: 8 | G22: 13 | H22: 5 | I22: 7 | J22: 2 | K22: 7 | L22: 5 | P22: =IF(COUNT($F22:$O22)=0,"",SUM($F22:$O22)) -> 47 | Q22: =IF(ISERROR(IF($P22="","",ROUND(($P22/$P$10)*$Q$10,2))),"",IF($P22="","",ROUND(($P22/$P$10)*$Q$10,2))) -> 58.75 | R22: =IF($Q22="","",ROUND($Q22*$R$10,2)) -> 17.63 | S22: 8 | T22: 11 | U22: 14 | V22: 7 | W22: 17 | X22: 9 | Y22: 20 | AC22: =IF(COUNT($S22:$AB22)=0,"",SUM($S22:$AB22)) -> 86 | AD22: =IF(ISERROR(IF($AC22="","",ROUND(($AC22/$AC$10)*$AD$10,2))),"",IF($AC22="","",ROUND(($AC22/$AC$10)*$AD$10,2))) -> 86 | AE22: =IF($AD22="","",ROUND($AD22*$AE$10,2)) -> 43 | AF22: 29 | AG22: =IF(ISERROR(IF($AF22="","",ROUND(($AF22/$AF$10)*$AG$10,2))),"",IF($AF22="","",ROUND(($AF22/$AF$10)*$AG$10,2))) -> 58 | AH22: =IF($AG22="","",ROUND($AG22*$AH$10,2)) -> 11.6 | AI22: =IF(ISERROR(IF($AF22="","",ROUND(SUM($R22,$AE22,$AH22),2))),"",IF($AF22="","",ROUND(SUM($R22,$AE22,$AH22),2))) -> 72.23 | AJ22: =IF(ISERROR(IF($AF22="","",VLOOKUP(AI22,TRANSMUTATION_TABLE,4,TRUE))),"",IF($AF22="","",VLOOKUP(AI22,TRANSMUTATION_TABLE,4,TRUE))) -> 82
A23: 12 | B23: ='INPUT DATA'!B23 -> 12. RELABO , PRINCE RUTHZNEIL SHELLORD C. | F23: 8 | G23: 11 | H23: 10 | I23: 8 | J23: 7 | K23: 9 | L23: 5 | P23: =IF(COUNT($F23:$O23)=0,"",SUM($F23:$O23)) -> 58 | Q23: =IF(ISERROR(IF($P23="","",ROUND(($P23/$P$10)*$Q$10,2))),"",IF($P23="","",ROUND(($P23/$P$10)*$Q$10,2))) -> 72.5 | R23: =IF($Q23="","",ROUND($Q23*$R$10,2)) -> 21.75 | S23: 7 | T23: 12 | U23: 12 | V23: 7 | W23: 12 | X23: 10 | Y23: 12 | AC23: =IF(COUNT($S23:$AB23)=0,"",SUM($S23:$AB23)) -> 72 | AD23: =IF(ISERROR(IF($AC23="","",ROUND(($AC23/$AC$10)*$AD$10,2))),"",IF($AC23="","",ROUND(($AC23/$AC$10)*$AD$10,2))) -> 72 | AE23: =IF($AD23="","",ROUND($AD23*$AE$10,2)) -> 36 | AF23: 46 | AG23: =IF(ISERROR(IF($AF23="","",ROUND(($AF23/$AF$10)*$AG$10,2))),"",IF($AF23="","",ROUND(($AF23/$AF$10)*$AG$10,2))) -> 92 | AH23: =IF($AG23="","",ROUND($AG23*$AH$10,2)) -> 18.4 | AI23: =IF(ISERROR(IF($AF23="","",ROUND(SUM($R23,$AE23,$AH23),2))),"",IF($AF23="","",ROUND(SUM($R23,$AE23,$AH23),2))) -> 76.15 | AJ23: =IF(ISERROR(IF($AF23="","",VLOOKUP(AI23,TRANSMUTATION_TABLE,4,TRUE))),"",IF($AF23="","",VLOOKUP(AI23,TRANSMUTATION_TABLE,4,TRUE))) -> 85
A24: 13 | B24: ='INPUT DATA'!B24 -> 13. SABONDO, KEYLETTE - TRANS IN | F24: 8 | G24: 4 | H24: 2 | I24: 8 | J24: 9 | K24: 11 | L24: 5 | P24: =IF(COUNT($F24:$O24)=0,"",SUM($F24:$O24)) -> 47 | Q24: =IF(ISERROR(IF($P24="","",ROUND(($P24/$P$10)*$Q$10,2))),"",IF($P24="","",ROUND(($P24/$P$10)*$Q$10,2))) -> 58.75 | R24: =IF($Q24="","",ROUND($Q24*$R$10,2)) -> 17.63 | S24: 7 | T24: 12 | U24: 12 | V24: 7 | W24: 15 | X24: 7 | Y24: 12 | AC24: =IF(COUNT($S24:$AB24)=0,"",SUM($S24:$AB24)) -> 72 | AD24: =IF(ISERROR(IF($AC24="","",ROUND(($AC24/$AC$10)*$AD$10,2))),"",IF($AC24="","",ROUND(($AC24/$AC$10)*$AD$10,2))) -> 72 | AE24: =IF($AD24="","",ROUND($AD24*$AE$10,2)) -> 36 | AF24: 47 | AG24: =IF(ISERROR(IF($AF24="","",ROUND(($AF24/$AF$10)*$AG$10,2))),"",IF($AF24="","",ROUND(($AF24/$AF$10)*$AG$10,2))) -> 94 | AH24: =IF($AG24="","",ROUND($AG24*$AH$10,2)) -> 18.8 | AI24: =IF(ISERROR(IF($AF24="","",ROUND(SUM($R24,$AE24,$AH24),2))),"",IF($AF24="","",ROUND(SUM($R24,$AE24,$AH24),2))) -> 72.43 | AJ24: =IF(ISERROR(IF($AF24="","",VLOOKUP(AI24,TRANSMUTATION_TABLE,4,TRUE))),"",IF($AF24="","",VLOOKUP(AI24,TRANSMUTATION_TABLE,4,TRUE))) -> 82
A25: 14 | B25: ='INPUT DATA'!B25 -> 14. SAN JUAN, THOMAS GREGORY GONZALES | F25: 9 | G25: 8 | H25: 5 | I25: 8 | J25: 10 | K25: 8 | L25: 5 | P25: =IF(COUNT($F25:$O25)=0,"",SUM($F25:$O25)) -> 53 | Q25: =IF(ISERROR(IF($P25="","",ROUND(($P25/$P$10)*$Q$10,2))),"",IF($P25="","",ROUND(($P25/$P$10)*$Q$10,2))) -> 66.25 | R25: =IF($Q25="","",ROUND($Q25*$R$10,2)) -> 19.88 | S25: 8 | T25: 13 | U25: 12 | V25: 8 | W25: 10 | X25: 10 | Y25: 17 | AC25: =IF(COUNT($S25:$AB25)=0,"",SUM($S25:$AB25)) -> 78 | AD25: =IF(ISERROR(IF($AC25="","",ROUND(($AC25/$AC$10)*$AD$10,2))),"",IF($AC25="","",ROUND(($AC25/$AC$10)*$AD$10,2))) -> 78 | AE25: =IF($AD25="","",ROUND($AD25*$AE$10,2)) -> 39 | AF25: 24 | AG25: =IF(ISERROR(IF($AF25="","",ROUND(($AF25/$AF$10)*$AG$10,2))),"",IF($AF25="","",ROUND(($AF25/$AF$10)*$AG$10,2))) -> 48 | AH25: =IF($AG25="","",ROUND($AG25*$AH$10,2)) -> 9.6 | AI25: =IF(ISERROR(IF($AF25="","",ROUND(SUM($R25,$AE25,$AH25),2))),"",IF($AF25="","",ROUND(SUM($R25,$AE25,$AH25),2))) -> 68.48 | AJ25: =IF(ISERROR(IF($AF25="","",VLOOKUP(AI25,TRANSMUTATION_TABLE,4,TRUE))),"",IF($AF25="","",VLOOKUP(AI25,TRANSMUTATION_TABLE,4,TRUE))) -> 80
A26: 15 | B26: ='INPUT DATA'!B26 -> 15. TAYAG , DENVER KIEL D. | F26: 7 | G26: 6 | H26: 5 | I26: 7 | J26: 7 | K26: 7 | L26: 10 | P26: =IF(COUNT($F26:$O26)=0,"",SUM($F26:$O26)) -> 49 | Q26: =IF(ISERROR(IF($P26="","",ROUND(($P26/$P$10)*$Q$10,2))),"",IF($P26="","",ROUND(($P26/$P$10)*$Q$10,2))) -> 61.25 | R26: =IF($Q26="","",ROUND($Q26*$R$10,2)) -> 18.38 | S26: 7 | T26: 12 | U26: 13 | V26: 7 | W26: 18 | X26: 10 | Y26: 20 | AC26: =IF(COUNT($S26:$AB26)=0,"",SUM($S26:$AB26)) -> 87 | AD26: =IF(ISERROR(IF($AC26="","",ROUND(($AC26/$AC$10)*$AD$10,2))),"",IF($AC26="","",ROUND(($AC26/$AC$10)*$AD$10,2))) -> 87 | AE26: =IF($AD26="","",ROUND($AD26*$AE$10,2)) -> 43.5 | AF26: 16 | AG26: =IF(ISERROR(IF($AF26="","",ROUND(($AF26/$AF$10)*$AG$10,2))),"",IF($AF26="","",ROUND(($AF26/$AF$10)*$AG$10,2))) -> 32 | AH26: =IF($AG26="","",ROUND($AG26*$AH$10,2)) -> 6.4 | AI26: =IF(ISERROR(IF($AF26="","",ROUND(SUM($R26,$AE26,$AH26),2))),"",IF($AF26="","",ROUND(SUM($R26,$AE26,$AH26),2))) -> 68.28 | AJ26: =IF(ISERROR(IF($AF26="","",VLOOKUP(AI26,TRANSMUTATION_TABLE,4,TRUE))),"",IF($AF26="","",VLOOKUP(AI26,TRANSMUTATION_TABLE,4,TRUE))) -> 80
A27: 16 | B27: ='INPUT DATA'!B27 -> 16. TUNGOL JOHANNES LISCOG | F27: 9 | G27: 10 | H27: 10 | I27: 8 | J27: 8 | K27: 9 | L27: 9 | P27: =IF(COUNT($F27:$O27)=0,"",SUM($F27:$O27)) -> 63 | Q27: =IF(ISERROR(IF($P27="","",ROUND(($P27/$P$10)*$Q$10,2))),"",IF($P27="","",ROUND(($P27/$P$10)*$Q$10,2))) -> 78.75 | R27: =IF($Q27="","",ROUND($Q27*$R$10,2)) -> 23.63 | S27: 8 | T27: 13 | U27: 14 | V27: 8 | W27: 18 | X27: 8 | Y27: 18 | AC27: =IF(COUNT($S27:$AB27)=0,"",SUM($S27:$AB27)) -> 87 | AD27: =IF(ISERROR(IF($AC27="","",ROUND(($AC27/$AC$10)*$AD$10,2))),"",IF($AC27="","",ROUND(($AC27/$AC$10)*$AD$10,2))) -> 87 | AE27: =IF($AD27="","",ROUND($AD27*$AE$10,2)) -> 43.5 | AF27: 40 | AG27: =IF(ISERROR(IF($AF27="","",ROUND(($AF27/$AF$10)*$AG$10,2))),"",IF($AF27="","",ROUND(($AF27/$AF$10)*$AG$10,2))) -> 80 | AH27: =IF($AG27="","",ROUND($AG27*$AH$10,2)) -> 16 | AI27: =IF(ISERROR(IF($AF27="","",ROUND(SUM($R27,$AE27,$AH27),2))),"",IF($AF27="","",ROUND(SUM($R27,$AE27,$AH27),2))) -> 83.13 | AJ27: =IF(ISERROR(IF($AF27="","",VLOOKUP(AI27,TRANSMUTATION_TABLE,4,TRUE))),"",IF($AF27="","",VLOOKUP(AI27,TRANSMUTATION_TABLE,4,TRUE))) -> 89
A28: 17 | B28: ='INPUT DATA'!B28 -> 17. TUNGOL, DANIEL MADDAWIN | F28: 8 | G28: 8 | H28: 8 | I28: 7 | J28: 5 | K28: 6 | L28: 7 | P28: =IF(COUNT($F28:$O28)=0,"",SUM($F28:$O28)) -> 49 | Q28: =IF(ISERROR(IF($P28="","",ROUND(($P28/$P$10)*$Q$10,2))),"",IF($P28="","",ROUND(($P28/$P$10)*$Q$10,2))) -> 61.25 | R28: =IF($Q28="","",ROUND($Q28*$R$10,2)) -> 18.38 | S28: 9 | T28: 12 | U28: 12 | V28: 9 | W28: 19 | X28: 10 | Y28: 18 | AC28: =IF(COUNT($S28:$AB28)=0,"",SUM($S28:$AB28)) -> 89 | AD28: =IF(ISERROR(IF($AC28="","",ROUND(($AC28/$AC$10)*$AD$10,2))),"",IF($AC28="","",ROUND(($AC28/$AC$10)*$AD$10,2))) -> 89 | AE28: =IF($AD28="","",ROUND($AD28*$AE$10,2)) -> 44.5 | AF28: 28 | AG28: =IF(ISERROR(IF($AF28="","",ROUND(($AF28/$AF$10)*$AG$10,2))),"",IF($AF28="","",ROUND(($AF28/$AF$10)*$AG$10,2))) -> 56 | AH28: =IF($AG28="","",ROUND($AG28*$AH$10,2)) -> 11.2 | AI28: =IF(ISERROR(IF($AF28="","",ROUND(SUM($R28,$AE28,$AH28),2))),"",IF($AF28="","",ROUND(SUM($R28,$AE28,$AH28),2))) -> 74.08 | AJ28: =IF(ISERROR(IF($AF28="","",VLOOKUP(AI28,TRANSMUTATION_TABLE,4,TRUE))),"",IF($AF28="","",VLOOKUP(AI28,TRANSMUTATION_TABLE,4,TRUE))) -> 83
A29: 18 | B29: ='INPUT DATA'!B29 -> 18. YUTUC , MARC ANDREI A. | F29: 8 | G29: 11 | H29: 5 | I29: 7 | J29: 7 | K29: 10 | L29: 10 | P29: =IF(COUNT($F29:$O29)=0,"",SUM($F29:$O29)) -> 58 | Q29: =IF(ISERROR(IF($P29="","",ROUND(($P29/$P$10)*$Q$10,2))),"",IF($P29="","",ROUND(($P29/$P$10)*$Q$10,2))) -> 72.5 | R29: =IF($Q29="","",ROUND($Q29*$R$10,2)) -> 21.75 | S29: 8 | T29: 12 | U29: 12 | V29: 7 | W29: 10 | X29: 10 | Y29: 17 | AC29: =IF(COUNT($S29:$AB29)=0,"",SUM($S29:$AB29)) -> 76 | AD29: =IF(ISERROR(IF($AC29="","",ROUND(($AC29/$AC$10)*$AD$10,2))),"",IF($AC29="","",ROUND(($AC29/$AC$10)*$AD$10,2))) -> 76 | AE29: =IF($AD29="","",ROUND($AD29*$AE$10,2)) -> 38 | AF29: 10 | AG29: =IF(ISERROR(IF($AF29="","",ROUND(($AF29/$AF$10)*$AG$10,2))),"",IF($AF29="","",ROUND(($AF29/$AF$10)*$AG$10,2))) -> 20 | AH29: =IF($AG29="","",ROUND($AG29*$AH$10,2)) -> 4 | AI29: =IF(ISERROR(IF($AF29="","",ROUND(SUM($R29,$AE29,$AH29),2))),"",IF($AF29="","",ROUND(SUM($R29,$AE29,$AH29),2))) -> 63.75 | AJ29: =IF(ISERROR(IF($AF29="","",VLOOKUP(AI29,TRANSMUTATION_TABLE,4,TRUE))),"",IF($AF29="","",VLOOKUP(AI29,TRANSMUTATION_TABLE,4,TRUE))) -> 77
A30: 19 | B30: ='INPUT DATA'!B30 -> BALUYUT, JOHN ALBERT | F30: 8 | G30: 5 | H30: 10 | I30: 8 | J30: 5 | K30: 12 | L30: 10 | P30: =IF(COUNT($F30:$O30)=0,"",SUM($F30:$O30)) -> 58 | Q30: =IF(ISERROR(IF($P30="","",ROUND(($P30/$P$10)*$Q$10,2))),"",IF($P30="","",ROUND(($P30/$P$10)*$Q$10,2))) -> 72.5 | R30: =IF($Q30="","",ROUND($Q30*$R$10,2)) -> 21.75 | S30: 7 | T30: 11 | U30: 14 | V30: 7 | W30: 19 | X30: 10 | Y30: 18 | AC30: =IF(COUNT($S30:$AB30)=0,"",SUM($S30:$AB30)) -> 86 | AD30: =IF(ISERROR(IF($AC30="","",ROUND(($AC30/$AC$10)*$AD$10,2))),"",IF($AC30="","",ROUND(($AC30/$AC$10)*$AD$10,2))) -> 86 | AE30: =IF($AD30="","",ROUND($AD30*$AE$10,2)) -> 43 | AF30: 35 | AG30: =IF(ISERROR(IF($AF30="","",ROUND(($AF30/$AF$10)*$AG$10,2))),"",IF($AF30="","",ROUND(($AF30/$AF$10)*$AG$10,2))) -> 70 | AH30: =IF($AG30="","",ROUND($AG30*$AH$10,2)) -> 14 | AI30: =IF(ISERROR(IF($AF30="","",ROUND(SUM($R30,$AE30,$AH30),2))),"",IF($AF30="","",ROUND(SUM($R30,$AE30,$AH30),2))) -> 78.75 | AJ30: =IF(ISERROR(IF($AF30="","",VLOOKUP(AI30,TRANSMUTATION_TABLE,4,TRUE))),"",IF($AF30="","",VLOOKUP(AI30,TRANSMUTATION_TABLE,4,TRUE))) -> 86
A31: 20 | B31: ='INPUT DATA'!B31 -> CALBARRIO, PRINCE LIAM | P31: =IF(COUNT($F31:$O31)=0,"",SUM($F31:$O31)) | Q31: =IF(ISERROR(IF($P31="","",ROUND(($P31/$P$10)*$Q$10,2))),"",IF($P31="","",ROUND(($P31/$P$10)*$Q$10,2))) | R31: =IF($Q31="","",ROUND($Q31*$R$10,2)) | AC31: =IF(COUNT($S31:$AB31)=0,"",SUM($S31:$AB31)) | AD31: =IF(ISERROR(IF($AC31="","",ROUND(($AC31/$AC$10)*$AD$10,2))),"",IF($AC31="","",ROUND(($AC31/$AC$10)*$AD$10,2))) | AE31: =IF($AD31="","",ROUND($AD31*$AE$10,2)) | AG31: =IF(ISERROR(IF($AF31="","",ROUND(($AF31/$AF$10)*$AG$10,2))),"",IF($AF31="","",ROUND(($AF31/$AF$10)*$AG$10,2))) | AH31: =IF($AG31="","",ROUND($AG31*$AH$10,2)) | AI31: =IF(ISERROR(IF($AF31="","",ROUND(SUM($R31,$AE31,$AH31),2))),"",IF($AF31="","",ROUND(SUM($R31,$AE31,$AH31),2))) | AJ31: =IF(ISERROR(IF($AF31="","",VLOOKUP(AI31,TRANSMUTATION_TABLE,4,TRUE))),"",IF($AF31="","",VLOOKUP(AI31,TRANSMUTATION_TABLE,4,TRUE)))
A32: 21 | B32: ='INPUT DATA'!B32 -> 0 | P32: =IF(COUNT($F32:$O32)=0,"",SUM($F32:$O32)) | Q32: =IF(ISERROR(IF($P32="","",ROUND(($P32/$P$10)*$Q$10,2))),"",IF($P32="","",ROUND(($P32/$P$10)*$Q$10,2))) | R32: =IF($Q32="","",ROUND($Q32*$R$10,2)) | AC32: =IF(COUNT($S32:$AB32)=0,"",SUM($S32:$AB32)) | AD32: =IF(ISERROR(IF($AC32="","",ROUND(($AC32/$AC$10)*$AD$10,2))),"",IF($AC32="","",ROUND(($AC32/$AC$10)*$AD$10,2))) | AE32: =IF($AD32="","",ROUND($AD32*$AE$10,2)) | AG32: =IF(ISERROR(IF($AF32="","",ROUND(($AF32/$AF$10)*$AG$10,2))),"",IF($AF32="","",ROUND(($AF32/$AF$10)*$AG$10,2))) | AH32: =IF($AG32="","",ROUND($AG32*$AH$10,2)) | AI32: =IF(ISERROR(IF($AF32="","",ROUND(SUM($R32,$AE32,$AH32),2))),"",IF($AF32="","",ROUND(SUM($R32,$AE32,$AH32),2))) | AJ32: =IF(ISERROR(IF($AF32="","",VLOOKUP(AI32,TRANSMUTATION_TABLE,4,TRUE))),"",IF($AF32="","",VLOOKUP(AI32,TRANSMUTATION_TABLE,4,TRUE)))
A33: 22 | B33: ='INPUT DATA'!B33 -> 0 | P33: =IF(COUNT($F33:$O33)=0,"",SUM($F33:$O33)) | Q33: =IF(ISERROR(IF($P33="","",ROUND(($P33/$P$10)*$Q$10,2))),"",IF($P33="","",ROUND(($P33/$P$10)*$Q$10,2))) | R33: =IF($Q33="","",ROUND($Q33*$R$10,2)) | AC33: =IF(COUNT($S33:$AB33)=0,"",SUM($S33:$AB33)) | AD33: =IF(ISERROR(IF($AC33="","",ROUND(($AC33/$AC$10)*$AD$10,2))),"",IF($AC33="","",ROUND(($AC33/$AC$10)*$AD$10,2))) | AE33: =IF($AD33="","",ROUND($AD33*$AE$10,2)) | AG33: =IF(ISERROR(IF($AF33="","",ROUND(($AF33/$AF$10)*$AG$10,2))),"",IF($AF33="","",ROUND(($AF33/$AF$10)*$AG$10,2))) | AH33: =IF($AG33="","",ROUND($AG33*$AH$10,2)) | AI33: =IF(ISERROR(IF($AF33="","",ROUND(SUM($R33,$AE33,$AH33),2))),"",IF($AF33="","",ROUND(SUM($R33,$AE33,$AH33),2))) | AJ33: =IF(ISERROR(IF($AF33="","",VLOOKUP(AI33,TRANSMUTATION_TABLE,4,TRUE))),"",IF($AF33="","",VLOOKUP(AI33,TRANSMUTATION_TABLE,4,TRUE)))
A34: 23 | B34: ='INPUT DATA'!B34 -> 0 | P34: =IF(COUNT($F34:$O34)=0,"",SUM($F34:$O34)) | Q34: =IF(ISERROR(IF($P34="","",ROUND(($P34/$P$10)*$Q$10,2))),"",IF($P34="","",ROUND(($P34/$P$10)*$Q$10,2))) | R34: =IF($Q34="","",ROUND($Q34*$R$10,2)) | AC34: =IF(COUNT($S34:$AB34)=0,"",SUM($S34:$AB34)) | AD34: =IF(ISERROR(IF($AC34="","",ROUND(($AC34/$AC$10)*$AD$10,2))),"",IF($AC34="","",ROUND(($AC34/$AC$10)*$AD$10,2))) | AE34: =IF($AD34="","",ROUND($AD34*$AE$10,2)) | AG34: =IF(ISERROR(IF($AF34="","",ROUND(($AF34/$AF$10)*$AG$10,2))),"",IF($AF34="","",ROUND(($AF34/$AF$10)*$AG$10,2))) | AH34: =IF($AG34="","",ROUND($AG34*$AH$10,2)) | AI34: =IF(ISERROR(IF($AF34="","",ROUND(SUM($R34,$AE34,$AH34),2))),"",IF($AF34="","",ROUND(SUM($R34,$AE34,$AH34),2))) | AJ34: =IF(ISERROR(IF($AF34="","",VLOOKUP(AI34,TRANSMUTATION_TABLE,4,TRUE))),"",IF($AF34="","",VLOOKUP(AI34,TRANSMUTATION_TABLE,4,TRUE)))
A35: 24 | B35: ='INPUT DATA'!B35 -> 0 | P35: =IF(COUNT($F35:$O35)=0,"",SUM($F35:$O35)) | Q35: =IF(ISERROR(IF($P35="","",ROUND(($P35/$P$10)*$Q$10,2))),"",IF($P35="","",ROUND(($P35/$P$10)*$Q$10,2))) | R35: =IF($Q35="","",ROUND($Q35*$R$10,2)) | AC35: =IF(COUNT($S35:$AB35)=0,"",SUM($S35:$AB35)) | AD35: =IF(ISERROR(IF($AC35="","",ROUND(($AC35/$AC$10)*$AD$10,2))),"",IF($AC35="","",ROUND(($AC35/$AC$10)*$AD$10,2))) | AE35: =IF($AD35="","",ROUND($AD35*$AE$10,2)) | AG35: =IF(ISERROR(IF($AF35="","",ROUND(($AF35/$AF$10)*$AG$10,2))),"",IF($AF35="","",ROUND(($AF35/$AF$10)*$AG$10,2))) | AH35: =IF($AG35="","",ROUND($AG35*$AH$10,2)) | AI35: =IF(ISERROR(IF($AF35="","",ROUND(SUM($R35,$AE35,$AH35),2))),"",IF($AF35="","",ROUND(SUM($R35,$AE35,$AH35),2))) | AJ35: =IF(ISERROR(IF($AF35="","",VLOOKUP(AI35,TRANSMUTATION_TABLE,4,TRUE))),"",IF($AF35="","",VLOOKUP(AI35,TRANSMUTATION_TABLE,4,TRUE)))
A36: 25 | B36: ='INPUT DATA'!B36 -> 0 | P36: =IF(COUNT($F36:$O36)=0,"",SUM($F36:$O36)) | Q36: =IF(ISERROR(IF($P36="","",ROUND(($P36/$P$10)*$Q$10,2))),"",IF($P36="","",ROUND(($P36/$P$10)*$Q$10,2))) | R36: =IF($Q36="","",ROUND($Q36*$R$10,2)) | AC36: =IF(COUNT($S36:$AB36)=0,"",SUM($S36:$AB36)) | AD36: =IF(ISERROR(IF($AC36="","",ROUND(($AC36/$AC$10)*$AD$10,2))),"",IF($AC36="","",ROUND(($AC36/$AC$10)*$AD$10,2))) | AE36: =IF($AD36="","",ROUND($AD36*$AE$10,2)) | AG36: =IF(ISERROR(IF($AF36="","",ROUND(($AF36/$AF$10)*$AG$10,2))),"",IF($AF36="","",ROUND(($AF36/$AF$10)*$AG$10,2))) | AH36: =IF($AG36="","",ROUND($AG36*$AH$10,2)) | AI36: =IF(ISERROR(IF($AF36="","",ROUND(SUM($R36,$AE36,$AH36),2))),"",IF($AF36="","",ROUND(SUM($R36,$AE36,$AH36),2))) | AJ36: =IF(ISERROR(IF($AF36="","",VLOOKUP(AI36,TRANSMUTATION_TABLE,4,TRUE))),"",IF($AF36="","",VLOOKUP(AI36,TRANSMUTATION_TABLE,4,TRUE)))
A37: 26 | B37: ='INPUT DATA'!B37 -> 0 | P37: =IF(COUNT($F37:$O37)=0,"",SUM($F37:$O37)) | Q37: =IF(ISERROR(IF($P37="","",ROUND(($P37/$P$10)*$Q$10,2))),"",IF($P37="","",ROUND(($P37/$P$10)*$Q$10,2))) | R37: =IF($Q37="","",ROUND($Q37*$R$10,2)) | AC37: =IF(COUNT($S37:$AB37)=0,"",SUM($S37:$AB37)) | AD37: =IF(ISERROR(IF($AC37="","",ROUND(($AC37/$AC$10)*$AD$10,2))),"",IF($AC37="","",ROUND(($AC37/$AC$10)*$AD$10,2))) | AE37: =IF($AD37="","",ROUND($AD37*$AE$10,2)) | AG37: =IF(ISERROR(IF($AF37="","",ROUND(($AF37/$AF$10)*$AG$10,2))),"",IF($AF37="","",ROUND(($AF37/$AF$10)*$AG$10,2))) | AH37: =IF($AG37="","",ROUND($AG37*$AH$10,2)) | AI37: =IF(ISERROR(IF($AF37="","",ROUND(SUM($R37,$AE37,$AH37),2))),"",IF($AF37="","",ROUND(SUM($R37,$AE37,$AH37),2))) | AJ37: =IF(ISERROR(IF($AF37="","",VLOOKUP(AI37,TRANSMUTATION_TABLE,4,TRUE))),"",IF($AF37="","",VLOOKUP(AI37,TRANSMUTATION_TABLE,4,TRUE)))
A38: 27 | B38: ='INPUT DATA'!B38 -> 0 | P38: =IF(COUNT($F38:$O38)=0,"",SUM($F38:$O38)) | Q38: =IF(ISERROR(IF($P38="","",ROUND(($P38/$P$10)*$Q$10,2))),"",IF($P38="","",ROUND(($P38/$P$10)*$Q$10,2))) | R38: =IF($Q38="","",ROUND($Q38*$R$10,2)) | AC38: =IF(COUNT($S38:$AB38)=0,"",SUM($S38:$AB38)) | AD38: =IF(ISERROR(IF($AC38="","",ROUND(($AC38/$AC$10)*$AD$10,2))),"",IF($AC38="","",ROUND(($AC38/$AC$10)*$AD$10,2))) | AE38: =IF($AD38="","",ROUND($AD38*$AE$10,2)) | AG38: =IF(ISERROR(IF($AF38="","",ROUND(($AF38/$AF$10)*$AG$10,2))),"",IF($AF38="","",ROUND(($AF38/$AF$10)*$AG$10,2))) | AH38: =IF($AG38="","",ROUND($AG38*$AH$10,2)) | AI38: =IF(ISERROR(IF($AF38="","",ROUND(SUM($R38,$AE38,$AH38),2))),"",IF($AF38="","",ROUND(SUM($R38,$AE38,$AH38),2))) | AJ38: =IF(ISERROR(IF($AF38="","",VLOOKUP(AI38,TRANSMUTATION_TABLE,4,TRUE))),"",IF($AF38="","",VLOOKUP(AI38,TRANSMUTATION_TABLE,4,TRUE)))
A39: 28 | B39: ='INPUT DATA'!B39 -> 0 | P39: =IF(COUNT($F39:$O39)=0,"",SUM($F39:$O39)) | Q39: =IF(ISERROR(IF($P39="","",ROUND(($P39/$P$10)*$Q$10,2))),"",IF($P39="","",ROUND(($P39/$P$10)*$Q$10,2))) | R39: =IF($Q39="","",ROUND($Q39*$R$10,2)) | AC39: =IF(COUNT($S39:$AB39)=0,"",SUM($S39:$AB39)) | AD39: =IF(ISERROR(IF($AC39="","",ROUND(($AC39/$AC$10)*$AD$10,2))),"",IF($AC39="","",ROUND(($AC39/$AC$10)*$AD$10,2))) | AE39: =IF($AD39="","",ROUND($AD39*$AE$10,2)) | AG39: =IF(ISERROR(IF($AF39="","",ROUND(($AF39/$AF$10)*$AG$10,2))),"",IF($AF39="","",ROUND(($AF39/$AF$10)*$AG$10,2))) | AH39: =IF($AG39="","",ROUND($AG39*$AH$10,2)) | AI39: =IF(ISERROR(IF($AF39="","",ROUND(SUM($R39,$AE39,$AH39),2))),"",IF($AF39="","",ROUND(SUM($R39,$AE39,$AH39),2))) | AJ39: =IF(ISERROR(IF($AF39="","",VLOOKUP(AI39,TRANSMUTATION_TABLE,4,TRUE))),"",IF($AF39="","",VLOOKUP(AI39,TRANSMUTATION_TABLE,4,TRUE)))
A40: 29 | B40: ='INPUT DATA'!B40 -> 0 | P40: =IF(COUNT($F40:$O40)=0,"",SUM($F40:$O40)) | Q40: =IF(ISERROR(IF($P40="","",ROUND(($P40/$P$10)*$Q$10,2))),"",IF($P40="","",ROUND(($P40/$P$10)*$Q$10,2))) | R40: =IF($Q40="","",ROUND($Q40*$R$10,2)) | AC40: =IF(COUNT($S40:$AB40)=0,"",SUM($S40:$AB40)) | AD40: =IF(ISERROR(IF($AC40="","",ROUND(($AC40/$AC$10)*$AD$10,2))),"",IF($AC40="","",ROUND(($AC40/$AC$10)*$AD$10,2))) | AE40: =IF($AD40="","",ROUND($AD40*$AE$10,2)) | AG40: =IF(ISERROR(IF($AF40="","",ROUND(($AF40/$AF$10)*$AG$10,2))),"",IF($AF40="","",ROUND(($AF40/$AF$10)*$AG$10,2))) | AH40: =IF($AG40="","",ROUND($AG40*$AH$10,2)) | AI40: =IF(ISERROR(IF($AF40="","",ROUND(SUM($R40,$AE40,$AH40),2))),"",IF($AF40="","",ROUND(SUM($R40,$AE40,$AH40),2))) | AJ40: =IF(ISERROR(IF($AF40="","",VLOOKUP(AI40,TRANSMUTATION_TABLE,4,TRUE))),"",IF($AF40="","",VLOOKUP(AI40,TRANSMUTATION_TABLE,4,TRUE)))
A41: 30 | B41: ='INPUT DATA'!B41 -> 0 | P41: =IF(COUNT($F41:$O41)=0,"",SUM($F41:$O41)) | Q41: =IF(ISERROR(IF($P41="","",ROUND(($P41/$P$10)*$Q$10,2))),"",IF($P41="","",ROUND(($P41/$P$10)*$Q$10,2))) | R41: =IF($Q41="","",ROUND($Q41*$R$10,2)) | AC41: =IF(COUNT($S41:$AB41)=0,"",SUM($S41:$AB41)) | AD41: =IF(ISERROR(IF($AC41="","",ROUND(($AC41/$AC$10)*$AD$10,2))),"",IF($AC41="","",ROUND(($AC41/$AC$10)*$AD$10,2))) | AE41: =IF($AD41="","",ROUND($AD41*$AE$10,2)) | AG41: =IF(ISERROR(IF($AF41="","",ROUND(($AF41/$AF$10)*$AG$10,2))),"",IF($AF41="","",ROUND(($AF41/$AF$10)*$AG$10,2))) | AH41: =IF($AG41="","",ROUND($AG41*$AH$10,2)) | AI41: =IF(ISERROR(IF($AF41="","",ROUND(SUM($R41,$AE41,$AH41),2))),"",IF($AF41="","",ROUND(SUM($R41,$AE41,$AH41),2))) | AJ41: =IF(ISERROR(IF($AF41="","",VLOOKUP(AI41,TRANSMUTATION_TABLE,4,TRUE))),"",IF($AF41="","",VLOOKUP(AI41,TRANSMUTATION_TABLE,4,TRUE)))
A42: 31 | B42: ='INPUT DATA'!B42 -> 0 | P42: =IF(COUNT($F42:$O42)=0,"",SUM($F42:$O42)) | Q42: =IF(ISERROR(IF($P42="","",ROUND(($P42/$P$10)*$Q$10,2))),"",IF($P42="","",ROUND(($P42/$P$10)*$Q$10,2))) | R42: =IF($Q42="","",ROUND($Q42*$R$10,2)) | AC42: =IF(COUNT($S42:$AB42)=0,"",SUM($S42:$AB42)) | AD42: =IF(ISERROR(IF($AC42="","",ROUND(($AC42/$AC$10)*$AD$10,2))),"",IF($AC42="","",ROUND(($AC42/$AC$10)*$AD$10,2))) | AE42: =IF($AD42="","",ROUND($AD42*$AE$10,2)) | AG42: =IF(ISERROR(IF($AF42="","",ROUND(($AF42/$AF$10)*$AG$10,2))),"",IF($AF42="","",ROUND(($AF42/$AF$10)*$AG$10,2))) | AH42: =IF($AG42="","",ROUND($AG42*$AH$10,2)) | AI42: =IF(ISERROR(IF($AF42="","",ROUND(SUM($R42,$AE42,$AH42),2))),"",IF($AF42="","",ROUND(SUM($R42,$AE42,$AH42),2))) | AJ42: =IF(ISERROR(IF($AF42="","",VLOOKUP(AI42,TRANSMUTATION_TABLE,4,TRUE))),"",IF($AF42="","",VLOOKUP(AI42,TRANSMUTATION_TABLE,4,TRUE)))
... A61: 50 | B61: ='INPUT DATA'!B61 -> 0 | P61: =IF(COUNT($F61:$O61)=0,"",SUM($F61:$O61)) | Q61: =IF(ISERROR(IF($P61="","",ROUND(($P61/$P$10)*$Q$10,2))),"",IF($P61="","",ROUND(($P61/$P$10)*$Q$10,2))) | R61: =IF($Q61="","",ROUND($Q61*$R$10,2)) | AC61: =IF(COUNT($S61:$AB61)=0,"",SUM($S61:$AB61)) | AD61: =IF(ISERROR(IF($AC61="","",ROUND(($AC61/$AC$10)*$AD$10,2))),"",IF($AC61="","",ROUND(($AC61/$AC$10)*$AD$10,2))) | AE61: =IF($AD61="","",ROUND($AD61*$AE$10,2)) | AG61: =IF(ISERROR(IF($AF61="","",ROUND(($AF61/$AF$10)*$AG$10,2))),"",IF($AF61="","",ROUND(($AF61/$AF$10)*$AG$10,2))) | AH61: =IF($AG61="","",ROUND($AG61*$AH$10,2)) | AI61: =IF(ISERROR(IF($AF61="","",ROUND(SUM($R61,$AE61,$AH61),2))),"",IF($AF61="","",ROUND(SUM($R61,$AE61,$AH61),2))) | AJ61: =IF(ISERROR(IF($AF61="","",VLOOKUP(AI61,TRANSMUTATION_TABLE,4,TRUE))),"",IF($AF61="","",VLOOKUP(AI61,TRANSMUTATION_TABLE,4,TRUE)))
...

Sheet EsP_Q2
A1: Official E-Class Record in K to 12 Curriculum
C4: REGION | G4: ='INPUT DATA'!G4 -> III | L4: DIVISION | O4: ='INPUT DATA'!O4 -> CITY OF SAN FDO. | T4: DISTRICT | X4: ='INPUT DATA'!X4 -> NORTH
B5: SCHOOL NAME | G5: ='INPUT DATA'!G5 -> TELABASTAGAN INTEGRATED SCHOOL | T5: SCHOOL ID | X5: ='INPUT DATA'!X5 -> 500144 | AD5: SCHOOL YEAR | AG5: ='INPUT DATA'!AG5 -> 2024-2025
A7: SECOND QUARTER | F7: GRADE & SECTION: | K7: ='INPUT DATA'!K7 -> VI-Venus | Q7: TEACHER: | S7: ='INPUT DATA'!S7 -> ADELIA M. MANARANG | AC7: SUBJECT: | AG7: ='INPUT DATA'!AG7 -> EDUKASYON SA PAGPAPAKATAO
B8: LEARNERS' NAMES | F8: WRITTEN WORKS (30%) | S8: PERFORMANCE TASKS (50%) | AF8: QUARTERLY ASSESSMENT (20%) | AI8: Initial | AJ8: Quarterly
F9: 1 | G9: 2 | H9: 3 | I9: 4 | J9: 5 | K9: 6 | L9: 7 | M9: 8 | N9: 9 | O9: 10 | P9: Total | Q9: PS | R9: WS | S9: 1 | T9: 2 | U9: 3 | V9: 4 | W9: 5 | X9: 6 | Y9: 7 | Z9: 8 | AA9: 9 | AB9: 10 | AC9: Total | AD9: PS | AE9: WS | AF9: 1 | AG9: PS | AH9: WS | AI9: Grade | AJ9: Grade
B10: HIGHEST POSSIBLE SCORE | F10: 10 | G10: 10 | H10: 10 | I10: 20 | J10: 11 | K10: 10 | P10: =IF(COUNT($F10:$O10)=0,"",SUM($F10:$O10)) -> 71 | Q10: 100 | R10: 0.3 | S10: 10 | T10: 20 | U10: 10 | V10: 20 | W10: 20 | X10: 15 | AC10: =IF(COUNT($S10:$AB10)=0,"",SUM($S10:$AB10)) -> 95 | AD10: 100 | AE10: 0.5 | AF10: 50 | AG10: 100 | AH10: 0.2
B11: MALE
A12: 1 | B12: ='INPUT DATA'!B12 -> 1. ARCEO, MARCUS ANDREW B. | F12: 8 | G12: 2 | H12: 4 | I12: 15 | J12: 10 | P12: =IF(COUNT($F12:$O12)=0,"",SUM($F12:$O12)) -> 39 | Q12: =IF(ISERROR(IF($P12="","",ROUND(($P12/$P$10)*$Q$10,2))),"",IF($P12="","",ROUND(($P12/$P$10)*$Q$10,2))) -> 54.93 | R12: =IF($Q12="","",ROUND($Q12*$R$10,2)) -> 16.48 | S12: 7 | T12: 17 | U12: 7 | V12: 17 | W12: 19 | AC12: =IF(COUNT($S12:$AB12)=0,"",SUM($S12:$AB12)) -> 67 | AD12: =IF(ISERROR(IF($AC12="","",ROUND(($AC12/$AC$10)*$AD$10,2))),"",IF($AC12="","",ROUND(($AC12/$AC$10)*$AD$10,2))) -> 70.53 | AE12: =IF($AD12="","",ROUND($AD12*$AE$10,2)) -> 35.27 | AF12: 50 | AG12: =IF(ISERROR(IF($AF12="","",ROUND(($AF12/$AF$10)*$AG$10,2))),"",IF($AF12="","",ROUND(($AF12/$AF$10)*$AG$10,2))) -> 100 | AH12: =IF($AG12="","",ROUND($AG12*$AH$10,2)) -> 20 | AI12: =IF(ISERROR(IF($AF12="","",ROUND(SUM($R12,$AE12,$AH12),2))),"",IF($AF12="","",ROUND(SUM($R12,$AE12,$AH12),2))) -> 71.75 | AJ12: =IF(ISERROR(IF($AF12="","",VLOOKUP(AI12,TRANSMUTATION_TABLE,4,TRUE))),"",IF($AF12="","",VLOOKUP(AI12,TRANSMUTATION_TABLE,4,TRUE))) -> 82
A13: 2 | B13: ='INPUT DATA'!B13 -> 2. CARIŇO, TOEBY YHAEL ANGELES | F13: 9 | G13: 8 | H13: 8 | I13: 20 | J13: 10 | K13: 10 | P13: =IF(COUNT($F13:$O13)=0,"",SUM($F13:$O13)) -> 65 | Q13: =IF(ISERROR(IF($P13="","",ROUND(($P13/$P$10)*$Q$10,2))),"",IF($P13="","",ROUND(($P13/$P$10)*$Q$10,2))) -> 91.55 | R13: =IF($Q13="","",ROUND($Q13*$R$10,2)) -> 27.47 | S13: 8 | T13: 18 | U13: 8 | V13: 20 | W13: 10 | X13: 15 | AC13: =IF(COUNT($S13:$AB13)=0,"",SUM($S13:$AB13)) -> 79 | AD13: =IF(ISERROR(IF($AC13="","",ROUND(($AC13/$AC$10)*$AD$10,2))),"",IF($AC13="","",ROUND(($AC13/$AC$10)*$AD$10,2))) -> 83.16 | AE13: =IF($AD13="","",ROUND($AD13*$AE$10,2)) -> 41.58 | AF13: 45 | AG13: =IF(ISERROR(IF($AF13="","",ROUND(($AF13/$AF$10)*$AG$10,2))),"",IF($AF13="","",ROUND(($AF13/$AF$10)*$AG$10,2))) -> 90 | AH13: =IF($AG13="","",ROUND($AG13*$AH$10,2)) -> 18 | AI13: =IF(ISERROR(IF($AF13="","",ROUND(SUM($R13,$AE13,$AH13),2))),"",IF($AF13="","",ROUND(SUM($R13,$AE13,$AH13),2))) -> 87.05 | AJ13: =IF(ISERROR(IF($AF13="","",VLOOKUP(AI13,TRANSMUTATION_TABLE,4,TRUE))),"",IF($AF13="","",VLOOKUP(AI13,TRANSMUTATION_TABLE,4,TRUE))) -> 91
A14: 3 | B14: ='INPUT DATA'!B14 -> 3. DE GUZMAN , YUAN KYLER D. | F14: 9 | G14: 8 | H14: 7 | I14: 18 | J14: 7 | K14: 10 | P14: =IF(COUNT($F14:$O14)=0,"",SUM($F14:$O14)) -> 59 | Q14: =IF(ISERROR(IF($P14="","",ROUND(($P14/$P$10)*$Q$10,2))),"",IF($P14="","",ROUND(($P14/$P$10)*$Q$10,2))) -> 83.1 | R14: =IF($Q14="","",ROUND($Q14*$R$10,2)) -> 24.93 | S14: 7 | T14: 18 | U14: 6 | V14: 19 | X14: 15 | AC14: =IF(COUNT($S14:$AB14)=0,"",SUM($S14:$AB14)) -> 65 | AD14: =IF(ISERROR(IF($AC14="","",ROUND(($AC14/$AC$10)*$AD$10,2))),"",IF($AC14="","",ROUND(($AC14/$AC$10)*$AD$10,2))) -> 68.42 | AE14: =IF($AD14="","",ROUND($AD14*$AE$10,2)) -> 34.21 | AF14: 50 | AG14: =IF(ISERROR(IF($AF14="","",ROUND(($AF14/$AF$10)*$AG$10,2))),"",IF($AF14="","",ROUND(($AF14/$AF$10)*$AG$10,2))) -> 100 | AH14: =IF($AG14="","",ROUND($AG14*$AH$10,2)) -> 20 | AI14: =IF(ISERROR(IF($AF14="","",ROUND(SUM($R14,$AE14,$AH14),2))),"",IF($AF14="","",ROUND(SUM($R14,$AE14,$AH14),2))) -> 79.14 | AJ14: =IF(ISERROR(IF($AF14="","",VLOOKUP(AI14,TRANSMUTATION_TABLE,4,TRUE))),"",IF($AF14="","",VLOOKUP(AI14,TRANSMUTATION_TABLE,4,TRUE))) -> 86
A15: 4 | B15: ='INPUT DATA'!B15 -> 4. DE LEON ERVIC MARQUITO | P15: =IF(COUNT($F15:$O15)=0,"",SUM($F15:$O15)) | Q15: =IF(ISERROR(IF($P15="","",ROUND(($P15/$P$10)*$Q$10,2))),"",IF($P15="","",ROUND(($P15/$P$10)*$Q$10,2))) | R15: =IF($Q15="","",ROUND($Q15*$R$10,2)) | AC15: =IF(COUNT($S15:$AB15)=0,"",SUM($S15:$AB15)) | AD15: =IF(ISERROR(IF($AC15="","",ROUND(($AC15/$AC$10)*$AD$10,2))),"",IF($AC15="","",ROUND(($AC15/$AC$10)*$AD$10,2))) | AE15: =IF($AD15="","",ROUND($AD15*$AE$10,2)) | AG15: =IF(ISERROR(IF($AF15="","",ROUND(($AF15/$AF$10)*$AG$10,2))),"",IF($AF15="","",ROUND(($AF15/$AF$10)*$AG$10,2))) | AH15: =IF($AG15="","",ROUND($AG15*$AH$10,2)) | AI15: =IF(ISERROR(IF($AF15="","",ROUND(SUM($R15,$AE15,$AH15),2))),"",IF($AF15="","",ROUND(SUM($R15,$AE15,$AH15),2))) | AJ15: =IF(ISERROR(IF($AF15="","",VLOOKUP(AI15,TRANSMUTATION_TABLE,4,TRUE))),"",IF($AF15="","",VLOOKUP(AI15,TRANSMUTATION_TABLE,4,TRUE)))
A16: 5 | B16: ='INPUT DATA'!B16 -> 5. DELA CRUZ, GIANVER JEAN DOMINGGO | F16: 8 | H16: 4 | P16: =IF(COUNT($F16:$O16)=0,"",SUM($F16:$O16)) -> 12 | Q16: =IF(ISERROR(IF($P16="","",ROUND(($P16/$P$10)*$Q$10,2))),"",IF($P16="","",ROUND(($P16/$P$10)*$Q$10,2))) -> 16.9 | R16: =IF($Q16="","",ROUND($Q16*$R$10,2)) -> 5.07 | S16: 7 | T16: 18 | U16: 7 | V16: 12 | W16: 9 | AC16: =IF(COUNT($S16:$AB16)=0,"",SUM($S16:$AB16)) -> 53 | AD16: =IF(ISERROR(IF($AC16="","",ROUND(($AC16/$AC$10)*$AD$10,2))),"",IF($AC16="","",ROUND(($AC16/$AC$10)*$AD$10,2))) -> 55.79 | AE16: =IF($AD16="","",ROUND($AD16*$AE$10,2)) -> 27.9 | AF16: 45 | AG16: =IF(ISERROR(IF($AF16="","",ROUND(($AF16/$AF$10)*$AG$10,2))),"",IF($AF16="","",ROUND(($AF16/$AF$10)*$AG$10,2))) -> 90 | AH16: =IF($AG16="","",ROUND($AG16*$AH$10,2)) -> 18 | AI16: =IF(ISERROR(IF($AF16="","",ROUND(SUM($R16,$AE16,$AH16),2))),"",IF($AF16="","",ROUND(SUM($R16,$AE16,$AH16),2))) -> 50.97 | AJ16: =IF(ISERROR(IF($AF16="","",VLOOKUP(AI16,TRANSMUTATION_TABLE,4,TRUE))),"",IF($AF16="","",VLOOKUP(AI16,TRANSMUTATION_TABLE,4,TRUE))) -> 72
A17: 6 | B17: ='INPUT DATA'!B17 -> 6. LOMANGGYA, JON DAVID P. | F17: 9 | G17: 10 | H17: 9 | I17: 20 | J17: 9 | K17: 10 | P17: =IF(COUNT($F17:$O17)=0,"",SUM($F17:$O17)) -> 67 | Q17: =IF(ISERROR(IF($P17="","",ROUND(($P17/$P$10)*$Q$10,2))),"",IF($P17="","",ROUND(($P17/$P$10)*$Q$10,2))) -> 94.37 | R17: =IF($Q17="","",ROUND($Q17*$R$10,2)) -> 28.31 | S17: 9 | T17: 19 | U17: 9 | V17: 7 | W17: 20 | X17: 15 | AC17: =IF(COUNT($S17:$AB17)=0,"",SUM($S17:$AB17)) -> 79 | AD17: =IF(ISERROR(IF($AC17="","",ROUND(($AC17/$AC$10)*$AD$10,2))),"",IF($AC17="","",ROUND(($AC17/$AC$10)*$AD$10,2))) -> 83.16 | AE17: =IF($AD17="","",ROUND($AD17*$AE$10,2)) -> 41.58 | AF17: 34 | AG17: =IF(ISERROR(IF($AF17="","",ROUND(($AF17/$AF$10)*$AG$10,2))),"",IF($AF17="","",ROUND(($AF17/$AF$10)*$AG$10,2))) -> 68 | AH17: =IF($AG17="","",ROUND($AG17*$AH$10,2)) -> 13.6 | AI17: =IF(ISERROR(IF($AF17="","",ROUND(SUM($R17,$AE17,$AH17),2))),"",IF($AF17="","",ROUND(SUM($R17,$AE17,$AH17),2))) -> 83.49 | AJ17: =IF(ISERROR(IF($AF17="","",VLOOKUP(AI17,TRANSMUTATION_TABLE,4,TRUE))),"",IF($AF17="","",VLOOKUP(AI17,TRANSMUTATION_TABLE,4,TRUE))) -> 89
A18: 7 | B18: ='INPUT DATA'!B18 -> 7. LULU , RHENZ RUZZEL G. | F18: 7 | G18: 10 | H18: 7 | I18: 20 | J18: 11 | K18: 8 | P18: =IF(COUNT($F18:$O18)=0,"",SUM($F18:$O18)) -> 63 | Q18: =IF(ISERROR(IF($P18="","",ROUND(($P18/$P$10)*$Q$10,2))),"",IF($P18="","",ROUND(($P18/$P$10)*$Q$10,2))) -> 88.73 | R18: =IF($Q18="","",ROUND($Q18*$R$10,2)) -> 26.62 | S18: 9 | T18: 18 | U18: 8 | V18: 19 | W18: 19 | X18: 15 | AC18: =IF(COUNT($S18:$AB18)=0,"",SUM($S18:$AB18)) -> 88 | AD18: =IF(ISERROR(IF($AC18="","",ROUND(($AC18/$AC$10)*$AD$10,2))),"",IF($AC18="","",ROUND(($AC18/$AC$10)*$AD$10,2))) -> 92.63 | AE18: =IF($AD18="","",ROUND($AD18*$AE$10,2)) -> 46.32 | AF18: 34 | AG18: =IF(ISERROR(IF($AF18="","",ROUND(($AF18/$AF$10)*$AG$10,2))),"",IF($AF18="","",ROUND(($AF18/$AF$10)*$AG$10,2))) -> 68 | AH18: =IF($AG18="","",ROUND($AG18*$AH$10,2)) -> 13.6 | AI18: =IF(ISERROR(IF($AF18="","",ROUND(SUM($R18,$AE18,$AH18),2))),"",IF($AF18="","",ROUND(SUM($R18,$AE18,$AH18),2))) -> 86.54 | AJ18: =IF(ISERROR(IF($AF18="","",VLOOKUP(AI18,TRANSMUTATION_TABLE,4,TRUE))),"",IF($AF18="","",VLOOKUP(AI18,TRANSMUTATION_TABLE,4,TRUE))) -> 91
A19: 8 | B19: ='INPUT DATA'!B19 -> 8. MACAPAGAL, LACSON JR. P. | D19: 0 | F19: 8 | G19: 5 | P19: =IF(COUNT($F19:$O19)=0,"",SUM($F19:$O19)) -> 13 | Q19: =IF(ISERROR(IF($P19="","",ROUND(($P19/$P$10)*$Q$10,2))),"",IF($P19="","",ROUND(($P19/$P$10)*$Q$10,2))) -> 18.31 | R19: =IF($Q19="","",ROUND($Q19*$R$10,2)) -> 5.49 | S19: 6 | T19: 19 | AC19: =IF(COUNT($S19:$AB19)=0,"",SUM($S19:$AB19)) -> 25 | AD19: =IF(ISERROR(IF($AC19="","",ROUND(($AC19/$AC$10)*$AD$10,2))),"",IF($AC19="","",ROUND(($AC19/$AC$10)*$AD$10,2))) -> 26.32 | AE19: =IF($AD19="","",ROUND($AD19*$AE$10,2)) -> 13.16 | AF19: 23 | AG19: =IF(ISERROR(IF($AF19="","",ROUND(($AF19/$AF$10)*$AG$10,2))),"",IF($AF19="","",ROUND(($AF19/$AF$10)*$AG$10,2))) -> 46 | AH19: =IF($AG19="","",ROUND($AG19*$AH$10,2)) -> 9.2 | AI19: =IF(ISERROR(IF($AF19="","",ROUND(SUM($R19,$AE19,$AH19),2))),"",IF($AF19="","",ROUND(SUM($R19,$AE19,$AH19),2))) -> 27.85 | AJ19: =IF(ISERROR(IF($AF19="","",VLOOKUP(AI19,TRANSMUTATION_TABLE,4,TRUE))),"",IF($AF19="","",VLOOKUP(AI19,TRANSMUTATION_TABLE,4,TRUE))) -> 66
A20: 9 | B20: ='INPUT DATA'!B20 -> 9. ORLAIN, TERENCE JERIEL D. | F20: 7 | G20: 8 | H20: 8 | J20: 10 | K20: 10 | P20: =IF(COUNT($F20:$O20)=0,"",SUM($F20:$O20)) -> 43 | Q20: =IF(ISERROR(IF($P20="","",ROUND(($P20/$P$10)*$Q$10,2))),"",IF($P20="","",ROUND(($P20/$P$10)*$Q$10,2))) -> 60.56 | R20: =IF($Q20="","",ROUND($Q20*$R$10,2)) -> 18.17 | S20: 7 | T20: 19 | U20: 7 | W20: 13 | X20: 14 | AC20: =IF(COUNT($S20:$AB20)=0,"",SUM($S20:$AB20)) -> 60 | AD20: =IF(ISERROR(IF($AC20="","",ROUND(($AC20/$AC$10)*$AD$10,2))),"",IF($AC20="","",ROUND(($AC20/$AC$10)*$AD$10,2))) -> 63.16 | AE20: =IF($AD20="","",ROUND($AD20*$AE$10,2)) -> 31.58 | AF20: 43 | AG20: =IF(ISERROR(IF($AF20="","",ROUND(($AF20/$AF$10)*$AG$10,2))),"",IF($AF20="","",ROUND(($AF20/$AF$10)*$AG$10,2))) -> 86 | AH20: =IF($AG20="","",ROUND($AG20*$AH$10,2)) -> 17.2 | AI20: =IF(ISERROR(IF($AF20="","",ROUND(SUM($R20,$AE20,$AH20),2))),"",IF($AF20="","",ROUND(SUM($R20,$AE20,$AH20),2))) -> 66.95 | AJ20: =IF(ISERROR(IF($AF20="","",VLOOKUP(AI20,TRANSMUTATION_TABLE,4,TRUE))),"",IF($AF20="","",VLOOKUP(AI20,TRANSMUTATION_TABLE,4,TRUE))) -> 79
A21: 10 | B21: ='INPUT DATA'!B21 -> 10. QUIAMBAO, JOHN LOR DELA FUENTE | F21: 8 | K21: 10 | P21: =IF(COUNT($F21:$O21)=0,"",SUM($F21:$O21)) -> 18 | Q21: =IF(ISERROR(IF($P21="","",ROUND(($P21/$P$10)*$Q$10,2))),"",IF($P21="","",ROUND(($P21/$P$10)*$Q$10,2))) -> 25.35 | R21: =IF($Q21="","",ROUND($Q21*$R$10,2)) -> 7.61 | S21: 8 | T21: 18 | U21: 7 | V21: 19 | W21: 8 | X21: 15 | AC21: =IF(COUNT($S21:$AB21)=0,"",SUM($S21:$AB21)) -> 75 | AD21: =IF(ISERROR(IF($AC21="","",ROUND(($AC21/$AC$10)*$AD$10,2))),"",IF($AC21="","",ROUND(($AC21/$AC$10)*$AD$10,2))) -> 78.95 | AE21: =IF($AD21="","",ROUND($AD21*$AE$10,2)) -> 39.48 | AF21: 45 | AG21: =IF(ISERROR(IF($AF21="","",ROUND(($AF21/$AF$10)*$AG$10,2))),"",IF($AF21="","",ROUND(($AF21/$AF$10)*$AG$10,2))) -> 90 | AH21: =IF($AG21="","",ROUND($AG21*$AH$10,2)) -> 18 | AI21: =IF(ISERROR(IF($AF21="","",ROUND(SUM($R21,$AE21,$AH21),2))),"",IF($AF21="","",ROUND(SUM($R21,$AE21,$AH21),2))) -> 65.09 | AJ21: =IF(ISERROR(IF($AF21="","",VLOOKUP(AI21,TRANSMUTATION_TABLE,4,TRUE))),"",IF($AF21="","",VLOOKUP(AI21,TRANSMUTATION_TABLE,4,TRUE))) -> 78
A22: 11 | B22: ='INPUT DATA'!B22 -> 11. RASCO, SEAN ROWEL TAMAYO | D22: 0 | F22: 7 | G22: 6 | H22: 4 | I22: 18 | J22: 4 | P22: =IF(COUNT($F22:$O22)=0,"",SUM($F22:$O22)) -> 39 | Q22: =IF(ISERROR(IF($P22="","",ROUND(($P22/$P$10)*$Q$10,2))),"",IF($P22="","",ROUND(($P22/$P$10)*$Q$10,2))) -> 54.93 | R22: =IF($Q22="","",ROUND($Q22*$R$10,2)) -> 16.48 | S22: 7 | T22: 18 | U22: 8 | W22: 6 | AC22: =IF(COUNT($S22:$AB22)=0,"",SUM($S22:$AB22)) -> 39 | AD22: =IF(ISERROR(IF($AC22="","",ROUND(($AC22/$AC$10)*$AD$10,2))),"",IF($AC22="","",ROUND(($AC22/$AC$10)*$AD$10,2))) -> 41.05 | AE22: =IF($AD22="","",ROUND($AD22*$AE$10,2)) -> 20.53 | AF22: 36 | AG22: =IF(ISERROR(IF($AF22="","",ROUND(($AF22/$AF$10)*$AG$10,2))),"",IF($AF22="","",ROUND(($AF22/$AF$10)*$AG$10,2))) -> 72 | AH22: =IF($AG22="","",ROUND($AG22*$AH$10,2)) -> 14.4 | AI22: =IF(ISERROR(IF($AF22="","",ROUND(SUM($R22,$AE22,$AH22),2))),"",IF($AF22="","",ROUND(SUM($R22,$AE22,$AH22),2))) -> 51.41 | AJ22: =IF(ISERROR(IF($AF22="","",VLOOKUP(AI22,TRANSMUTATION_TABLE,4,TRUE))),"",IF($AF22="","",VLOOKUP(AI22,TRANSMUTATION_TABLE,4,TRUE))) -> 72
A23: 12 | B23: ='INPUT DATA'!B23 -> 12. RELABO , PRINCE RUTHZNEIL SHELLORD C. | F23: 8 | G23: 6 | H23: 7 | I23: 20 | J23: 9 | K23: 9 | P23: =IF(COUNT($F23:$O23)=0,"",SUM($F23:$O23)) -> 59 | Q23: =IF(ISERROR(IF($P23="","",ROUND(($P23/$P$10)*$Q$10,2))),"",IF($P23="","",ROUND(($P23/$P$10)*$Q$10,2))) -> 83.1 | R23: =IF($Q23="","",ROUND($Q23*$R$10,2)) -> 24.93 | S23: 7 | T23: 19 | U23: 7 | W23: 10 | X23: 14 | AC23: =IF(COUNT($S23:$AB23)=0,"",SUM($S23:$AB23)) -> 57 | AD23: =IF(ISERROR(IF($AC23="","",ROUND(($AC23/$AC$10)*$AD$10,2))),"",IF($AC23="","",ROUND(($AC23/$AC$10)*$AD$10,2))) -> 60 | AE23: =IF($AD23="","",ROUND($AD23*$AE$10,2)) -> 30 | AF23: 34 | AG23: =IF(ISERROR(IF($AF23="","",ROUND(($AF23/$AF$10)*$AG$10,2))),"",IF($AF23="","",ROUND(($AF23/$AF$10)*$AG$10,2))) -> 68 | AH23: =IF($AG23="","",ROUND($AG23*$AH$10,2)) -> 13.6 | AI23: =IF(ISERROR(IF($AF23="","",ROUND(SUM($R23,$AE23,$AH23),2))),"",IF($AF23="","",ROUND(SUM($R23,$AE23,$AH23),2))) -> 68.53 | AJ23: =IF(ISERROR(IF($AF23="","",VLOOKUP(AI23,TRANSMUTATION_TABLE,4,TRUE))),"",IF($AF23="","",VLOOKUP(AI23,TRANSMUTATION_TABLE,4,TRUE))) -> 80
A24: 13 | B24: ='INPUT DATA'!B24 -> 13. SABONDO, KEYLETTE - TRANS IN | F24: 7 | H24: 5 | I24: 20 | J24: 9 | P24: =IF(COUNT($F24:$O24)=0,"",SUM($F24:$O24)) -> 41 | Q24: =IF(ISERROR(IF($P24="","",ROUND(($P24/$P$10)*$Q$10,2))),"",IF($P24="","",ROUND(($P24/$P$10)*$Q$10,2))) -> 57.75 | R24: =IF($Q24="","",ROUND($Q24*$R$10,2)) -> 17.33 | S24: 8 | T24: 18 | U24: 8 | V24: 5 | W24: 9 | X24: 10 | AC24: =IF(COUNT($S24:$AB24)=0,"",SUM($S24:$AB24)) -> 58 | AD24: =IF(ISERROR(IF($AC24="","",ROUND(($AC24/$AC$10)*$AD$10,2))),"",IF($AC24="","",ROUND(($AC24/$AC$10)*$AD$10,2))) -> 61.05 | AE24: =IF($AD24="","",ROUND($AD24*$AE$10,2)) -> 30.53 | AF24: 34 | AG24: =IF(ISERROR(IF($AF24="","",ROUND(($AF24/$AF$10)*$AG$10,2))),"",IF($AF24="","",ROUND(($AF24/$AF$10)*$AG$10,2))) -> 68 | AH24: =IF($AG24="","",ROUND($AG24*$AH$10,2)) -> 13.6 | AI24: =IF(ISERROR(IF($AF24="","",ROUND(SUM($R24,$AE24,$AH24),2))),"",IF($AF24="","",ROUND(SUM($R24,$AE24,$AH24),2))) -> 61.46 | AJ24: =IF(ISERROR(IF($AF24="","",VLOOKUP(AI24,TRANSMUTATION_TABLE,4,TRUE))),"",IF($AF24="","",VLOOKUP(AI24,TRANSMUTATION_TABLE,4,TRUE))) -> 75
A25: 14 | B25: ='INPUT DATA'!B25 -> 14. SAN JUAN, THOMAS GREGORY GONZALES | F25: 8 | G25: 5 | H25: 8 | I25: 18 | K25: 10 | P25: =IF(COUNT($F25:$O25)=0,"",SUM($F25:$O25)) -> 49 | Q25: =IF(ISERROR(IF($P25="","",ROUND(($P25/$P$10)*$Q$10,2))),"",IF($P25="","",ROUND(($P25/$P$10)*$Q$10,2))) -> 69.01 | R25: =IF($Q25="","",ROUND($Q25*$R$10,2)) -> 20.7 | S25: 7 | T25: 19 | U25: 7 | V25: 15 | AC25: =IF(COUNT($S25:$AB25)=0,"",SUM($S25:$AB25)) -> 48 | AD25: =IF(ISERROR(IF($AC25="","",ROUND(($AC25/$AC$10)*$AD$10,2))),"",IF($AC25="","",ROUND(($AC25/$AC$10)*$AD$10,2))) -> 50.53 | AE25: =IF($AD25="","",ROUND($AD25*$AE$10,2)) -> 25.27 | AF25: 23 | AG25: =IF(ISERROR(IF($AF25="","",ROUND(($AF25/$AF$10)*$AG$10,2))),"",IF($AF25="","",ROUND(($AF25/$AF$10)*$AG$10,2))) -> 46 | AH25: =IF($AG25="","",ROUND($AG25*$AH$10,2)) -> 9.2 | AI25: =IF(ISERROR(IF($AF25="","",ROUND(SUM($R25,$AE25,$AH25),2))),"",IF($AF25="","",ROUND(SUM($R25,$AE25,$AH25),2))) -> 55.17 | AJ25: =IF(ISERROR(IF($AF25="","",VLOOKUP(AI25,TRANSMUTATION_TABLE,4,TRUE))),"",IF($AF25="","",VLOOKUP(AI25,TRANSMUTATION_TABLE,4,TRUE))) -> 73
A26: 15 | B26: ='INPUT DATA'!B26 -> 15. TAYAG , DENVER KIEL D. | F26: 8 | G26: 5 | H26: 9 | I26: 18 | J26: 9 | P26: =IF(COUNT($F26:$O26)=0,"",SUM($F26:$O26)) -> 49 | Q26: =IF(ISERROR(IF($P26="","",ROUND(($P26/$P$10)*$Q$10,2))),"",IF($P26="","",ROUND(($P26/$P$10)*$Q$10,2))) -> 69.01 | R26: =IF($Q26="","",ROUND($Q26*$R$10,2)) -> 20.7 | S26: 7 | T26: 19 | U26: 8 | V26: 15 | W26: 10 | X26: 15 | AC26: =IF(COUNT($S26:$AB26)=0,"",SUM($S26:$AB26)) -> 74 | AD26: =IF(ISERROR(IF($AC26="","",ROUND(($AC26/$AC$10)*$AD$10,2))),"",IF($AC26="","",ROUND(($AC26/$AC$10)*$AD$10,2))) -> 77.89 | AE26: =IF($AD26="","",ROUND($AD26*$AE$10,2)) -> 38.95 | AF26: 34 | AG26: =IF(ISERROR(IF($AF26="","",ROUND(($AF26/$AF$10)*$AG$10,2))),"",IF($AF26="","",ROUND(($AF26/$AF$10)*$AG$10,2))) -> 68 | AH26: =IF($AG26="","",ROUND($AG26*$AH$10,2)) -> 13.6 | AI26: =IF(ISERROR(IF($AF26="","",ROUND(SUM($R26,$AE26,$AH26),2))),"",IF($AF26="","",ROUND(SUM($R26,$AE26,$AH26),2))) -> 73.25 | AJ26: =IF(ISERROR(IF($AF26="","",VLOOKUP(AI26,TRANSMUTATION_TABLE,4,TRUE))),"",IF($AF26="","",VLOOKUP(AI26,TRANSMUTATION_TABLE,4,TRUE))) -> 83
A27: 16 | B27: ='INPUT DATA'!B27 -> 16. TUNGOL JOHANNES LISCOG | F27: 7 | G27: 9 | H27: 7 | I27: 20 | J27: 9 | K27: 10 | P27: =IF(COUNT($F27:$O27)=0,"",SUM($F27:$O27)) -> 62 | Q27: =IF(ISERROR(IF($P27="","",ROUND(($P27/$P$10)*$Q$10,2))),"",IF($P27="","",ROUND(($P27/$P$10)*$Q$10,2))) -> 87.32 | R27: =IF($Q27="","",ROUND($Q27*$R$10,2)) -> 26.2 | S27: 7 | T27: 18 | U27: 7 | V27: 19 | W27: 10 | X27: 13 | AC27: =IF(COUNT($S27:$AB27)=0,"",SUM($S27:$AB27)) -> 74 | AD27: =IF(ISERROR(IF($AC27="","",ROUND(($AC27/$AC$10)*$AD$10,2))),"",IF($AC27="","",ROUND(($AC27/$AC$10)*$AD$10,2))) -> 77.89 | AE27: =IF($AD27="","",ROUND($AD27*$AE$10,2)) -> 38.95 | AF27: 50 | AG27: =IF(ISERROR(IF($AF27="","",ROUND(($AF27/$AF$10)*$AG$10,2))),"",IF($AF27="","",ROUND(($AF27/$AF$10)*$AG$10,2))) -> 100 | AH27: =IF($AG27="","",ROUND($AG27*$AH$10,2)) -> 20 | AI27: =IF(ISERROR(IF($AF27="","",ROUND(SUM($R27,$AE27,$AH27),2))),"",IF($AF27="","",ROUND(SUM($R27,$AE27,$AH27),2))) -> 85.15 | AJ27: =IF(ISERROR(IF($AF27="","",VLOOKUP(AI27,TRANSMUTATION_TABLE,4,TRUE))),"",IF($AF27="","",VLOOKUP(AI27,TRANSMUTATION_TABLE,4,TRUE))) -> 90
A28: 17 | B28: ='INPUT DATA'!B28 -> 17. TUNGOL, DANIEL MADDAWIN | F28: 8 | G28: 8 | H28: 6 | I28: 18 | J28: 11 | K28: 10 | P28: =IF(COUNT($F28:$O28)=0,"",SUM($F28:$O28)) -> 61 | Q28: =IF(ISERROR(IF($P28="","",ROUND(($P28/$P$10)*$Q$10,2))),"",IF($P28="","",ROUND(($P28/$P$10)*$Q$10,2))) -> 85.92 | R28: =IF($Q28="","",ROUND($Q28*$R$10,2)) -> 25.78 | S28: 8 | T28: 18 | U28: 9 | V28: 13 | W28: 20 | AC28: =IF(COUNT($S28:$AB28)=0,"",SUM($S28:$AB28)) -> 68 | AD28: =IF(ISERROR(IF($AC28="","",ROUND(($AC28/$AC$10)*$AD$10,2))),"",IF($AC28="","",ROUND(($AC28/$AC$10)*$AD$10,2))) -> 71.58 | AE28: =IF($AD28="","",ROUND($AD28*$AE$10,2)) -> 35.79 | AF28: 32 | AG28: =IF(ISERROR(IF($AF28="","",ROUND(($AF28/$AF$10)*$AG$10,2))),"",IF($AF28="","",ROUND(($AF28/$AF$10)*$AG$10,2))) -> 64 | AH28: =IF($AG28="","",ROUND($AG28*$AH$10,2)) -> 12.8 | AI28: =IF(ISERROR(IF($AF28="","",ROUND(SUM($R28,$AE28,$AH28),2))),"",IF($AF28="","",ROUND(SUM($R28,$AE28,$AH28),2))) -> 74.37 | AJ28: =IF(ISERROR(IF($AF28="","",VLOOKUP(AI28,TRANSMUTATION_TABLE,4,TRUE))),"",IF($AF28="","",VLOOKUP(AI28,TRANSMUTATION_TABLE,4,TRUE))) -> 83
A29: 18 | B29: ='INPUT DATA'!B29 -> 18. YUTUC , MARC ANDREI A. | F29: 9 | G29: 9 | H29: 8 | I29: 20 | J29: 8 | K29: 7 | P29: =IF(COUNT($F29:$O29)=0,"",SUM($F29:$O29)) -> 61 | Q29: =IF(ISERROR(IF($P29="","",ROUND(($P29/$P$10)*$Q$10,2))),"",IF($P29="","",ROUND(($P29/$P$10)*$Q$10,2))) -> 85.92 | R29: =IF($Q29="","",ROUND($Q29*$R$10,2)) -> 25.78 | S29: 8 | T29: 18 | U29: 7 | V29: 9 | W29: 18 | X29: 15 | AC29: =IF(COUNT($S29:$AB29)=0,"",SUM($S29:$AB29)) -> 75 | AD29: =IF(ISERROR(IF($AC29="","",ROUND(($AC29/$AC$10)*$AD$10,2))),"",IF($AC29="","",ROUND(($AC29/$AC$10)*$AD$10,2))) -> 78.95 | AE29: =IF($AD29="","",ROUND($AD29*$AE$10,2)) -> 39.48 | AF29: 45 | AG29: =IF(ISERROR(IF($AF29="","",ROUND(($AF29/$AF$10)*$AG$10,2))),"",IF($AF29="","",ROUND(($AF29/$AF$10)*$AG$10,2))) -> 90 | AH29: =IF($AG29="","",ROUND($AG29*$AH$10,2)) -> 18 | AI29: =IF(ISERROR(IF($AF29="","",ROUND(SUM($R29,$AE29,$AH29),2))),"",IF($AF29="","",ROUND(SUM($R29,$AE29,$AH29),2))) -> 83.26 | AJ29: =IF(ISERROR(IF($AF29="","",VLOOKUP(AI29,TRANSMUTATION_TABLE,4,TRUE))),"",IF($AF29="","",VLOOKUP(AI29,TRANSMUTATION_TABLE,4,TRUE))) -> 89
A30: 19 | B30: ='INPUT DATA'!B30 -> BALUYUT, JOHN ALBERT | F30: 7 | H30: 9 | I30: 15 | J30: 8 | K30: 10 | P30: =IF(COUNT($F30:$O30)=0,"",SUM($F30:$O30)) -> 49 | Q30: =IF(ISERROR(IF($P30="","",ROUND(($P30/$P$10)*$Q$10,2))),"",IF($P30="","",ROUND(($P30/$P$10)*$Q$10,2))) -> 69.01 | R30: =IF($Q30="","",ROUND($Q30*$R$10,2)) -> 20.7 | S30: 6 | T30: 18 | U30: 6 | V30: 10 | W30: 8 | X30: 13 | AC30: =IF(COUNT($S30:$AB30)=0,"",SUM($S30:$AB30)) -> 61 | AD30: =IF(ISERROR(IF($AC30="","",ROUND(($AC30/$AC$10)*$AD$10,2))),"",IF($AC30="","",ROUND(($AC30/$AC$10)*$AD$10,2))) -> 64.21 | AE30: =IF($AD30="","",ROUND($AD30*$AE$10,2)) -> 32.11 | AF30: 23 | AG30: =IF(ISERROR(IF($AF30="","",ROUND(($AF30/$AF$10)*$AG$10,2))),"",IF($AF30="","",ROUND(($AF30/$AF$10)*$AG$10,2))) -> 46 | AH30: =IF($AG30="","",ROUND($AG30*$AH$10,2)) -> 9.2 | AI30: =IF(ISERROR(IF($AF30="","",ROUND(SUM($R30,$AE30,$AH30),2))),"",IF($AF30="","",ROUND(SUM($R30,$AE30,$AH30),2))) -> 62.01 | AJ30: =IF(ISERROR(IF($AF30="","",VLOOKUP(AI30,TRANSMUTATION_TABLE,4,TRUE))),"",IF($AF30="","",VLOOKUP(AI30,TRANSMUTATION_TABLE,4,TRUE))) -> 76
A31: 20 | B31: ='INPUT DATA'!B31 -> CALBARRIO, PRINCE LIAM | F31: 8 | G31: 7 | H31: 7 | I31: 20 | J31: 9 | P31: =IF(COUNT($F31:$O31)=0,"",SUM($F31:$O31)) -> 51 | Q31: =IF(ISERROR(IF($P31="","",ROUND(($P31/$P$10)*$Q$10,2))),"",IF($P31="","",ROUND(($P31/$P$10)*$Q$10,2))) -> 71.83 | R31: =IF($Q31="","",ROUND($Q31*$R$10,2)) -> 21.55 | U31: 7 | V31: 17 | W31: 9 | X31: 15 | AC31: =IF(COUNT($S31:$AB31)=0,"",SUM($S31:$AB31)) -> 48 | AD31: =IF(ISERROR(IF($AC31="","",ROUND(($AC31/$AC$10)*$AD$10,2))),"",IF($AC31="","",ROUND(($AC31/$AC$10)*$AD$10,2))) -> 50.53 | AE31: =IF($AD31="","",ROUND($AD31*$AE$10,2)) -> 25.27 | AF31: 43 | AG31: =IF(ISERROR(IF($AF31="","",ROUND(($AF31/$AF$10)*$AG$10,2))),"",IF($AF31="","",ROUND(($AF31/$AF$10)*$AG$10,2))) -> 86 | AH31: =IF($AG31="","",ROUND($AG31*$AH$10,2)) -> 17.2 | AI31: =IF(ISERROR(IF($AF31="","",ROUND(SUM($R31,$AE31,$AH31),2))),"",IF($AF31="","",ROUND(SUM($R31,$AE31,$AH31),2))) -> 64.02 | AJ31: =IF(ISERROR(IF($AF31="","",VLOOKUP(AI31,TRANSMUTATION_TABLE,4,TRUE))),"",IF($AF31="","",VLOOKUP(AI31,TRANSMUTATION_TABLE,4,TRUE))) -> 77
